INFO b''
INFO b''
INFO b''
INFO b''
WARNING Not Found: /comment/comment/undefined
WARNING Not Found: /comment/comment/undefined
WARNING Not Found: /comment/comment/undefined
WARNING Not Found: /comment/comment/undefined
WARNING Not Found: /comment/comment/undefined
WARNING Not Found: /comment/comment/undefined
WARNING Not Found: /comment/comment/undefined
WARNING Not Found: /comment/comment/undefined
INFO b''
INFO b''
INFO b''
INFO b''
INFO b''
INFO b''
INFO b''
INFO b''
INFO b''
INFO b''
INFO b''
INFO b''
WARNING Not Found: /comment/comment/undefined
WARNING Not Found: /comment/comment/undefined
WARNING Not Found: /comment/comment/undefined
WARNING Not Found: /comment/comment/undefined
WARNING Not Found: /books/
WARNING Not Found: /books/
INFO b''
INFO b''
WARNING Not Found: /comment/comment/undefined
WARNING Not Found: /comment/comment/undefined
WARNING Not Found: /comment/comment/undefined
WARNING Not Found: /comment/comment/undefined
INFO b''
INFO b''
WARNING Not Found: /comment/comment/undefined
WARNING Not Found: /comment/comment/undefined
WARNING Not Found: /comment/comment/undefined
WARNING Not Found: /comment/comment/undefined
WARNING Not Found: /comment/comment/undefined
WARNING Not Found: /comment/comment/undefined
WARNING Not Found: /comment/comment/undefined
WARNING Not Found: /comment/comment/undefined
WARNING Not Found: /comment/comment/undefined
WARNING Not Found: /comment/comment/undefined
INFO b''
INFO b''
INFO b''
INFO b''
INFO b''
INFO b''
INFO b''
INFO b''
INFO b''
INFO b''
WARNING Not Found: /comment/comment/undefined
WARNING Not Found: /comment/comment/undefined
WARNING Not Found: /comment/comment/undefined
WARNING Not Found: /comment/comment/undefined
WARNING Not Found: /comment/comment/undefined
WARNING Not Found: /comment/comment/undefined
WARNING Not Found: /comment/comment/undefined
WARNING Not Found: /comment/comment/undefined
INFO b''
INFO b''
WARNING Not Found: /favicon.ico
WARNING Not Found: /favicon.ico
WARNING Not Found: /comment/comment/undefined
WARNING Not Found: /comment/comment/undefined
WARNING Not Found: /comment/comment/undefined
WARNING Not Found: /comment/comment/undefined
INFO b''
INFO b''
INFO b''
INFO b''
WARNING Not Found: /comment/comment/undefined
WARNING Not Found: /comment/comment/undefined
INFO b''
INFO b''
WARNING Not Found: /comment/comment/undefined
WARNING Not Found: /comment/comment/undefined
WARNING Not Found: /comment/comment/undefined
WARNING Not Found: /comment/comment/undefined
ERROR Internal Server Error: /order/check_pay/
Traceback (most recent call last):
  File "/home/f/myproject/venv/lib/python3.5/site-packages/django/core/handlers/base.py", line 132, in get_response
    response = wrapped_callback(request, *callback_args, **callback_kwargs)
  File "/home/f/myproject/mybookstore/utils/utils.py", line 11, in wrapper
    return view_func(request, *view_args, **view_kwargs)
  File "/home/f/myproject/mybookstore/order/views.py", line 264, in check_pay
    result = alipay.api_alipay_trade_query(order_id)
  File "/home/f/myproject/venv/lib/python3.5/site-packages/alipay/__init__.py", line 305, in api_alipay_trade_query
    return self._verify_and_return_sync_response(raw_string, "alipay_trade_query_response")
  File "/home/f/myproject/venv/lib/python3.5/site-packages/alipay/__init__.py", line 525, in _verify_and_return_sync_response
    raise AliPayValidationError
alipay.exceptions.AliPayValidationError
ERROR Internal Server Error: /order/check_pay/
Traceback (most recent call last):
  File "/home/f/myproject/venv/lib/python3.5/site-packages/django/core/handlers/base.py", line 132, in get_response
    response = wrapped_callback(request, *callback_args, **callback_kwargs)
  File "/home/f/myproject/mybookstore/utils/utils.py", line 11, in wrapper
    return view_func(request, *view_args, **view_kwargs)
  File "/home/f/myproject/mybookstore/order/views.py", line 264, in check_pay
    result = alipay.api_alipay_trade_query(order_id)
  File "/home/f/myproject/venv/lib/python3.5/site-packages/alipay/__init__.py", line 305, in api_alipay_trade_query
    return self._verify_and_return_sync_response(raw_string, "alipay_trade_query_response")
  File "/home/f/myproject/venv/lib/python3.5/site-packages/alipay/__init__.py", line 525, in _verify_and_return_sync_response
    raise AliPayValidationError
alipay.exceptions.AliPayValidationError
ERROR Internal Server Error: /
Traceback (most recent call last):
  File "/home/f/myproject/venv/lib/python3.5/site-packages/django/core/handlers/base.py", line 132, in get_response
    response = wrapped_callback(request, *callback_args, **callback_kwargs)
  File "/home/f/myproject/mybookstore/books/views.py", line 29, in index
    logger.info(request.url)
AttributeError: 'WSGIRequest' object has no attribute 'url'
ERROR Internal Server Error: /
Traceback (most recent call last):
  File "/home/f/myproject/venv/lib/python3.5/site-packages/django/core/handlers/base.py", line 132, in get_response
    response = wrapped_callback(request, *callback_args, **callback_kwargs)
  File "/home/f/myproject/mybookstore/books/views.py", line 29, in index
    logger.info(request.url)
AttributeError: 'WSGIRequest' object has no attribute 'url'
ERROR Internal Server Error: /
Traceback (most recent call last):
  File "/home/f/myproject/venv/lib/python3.5/site-packages/django/core/handlers/base.py", line 132, in get_response
    response = wrapped_callback(request, *callback_args, **callback_kwargs)
  File "/home/f/myproject/mybookstore/books/views.py", line 29, in index
    logger.info(request.url)
AttributeError: 'WSGIRequest' object has no attribute 'url'
ERROR Internal Server Error: /
Traceback (most recent call last):
  File "/home/f/myproject/venv/lib/python3.5/site-packages/django/core/handlers/base.py", line 132, in get_response
    response = wrapped_callback(request, *callback_args, **callback_kwargs)
  File "/home/f/myproject/mybookstore/books/views.py", line 29, in index
    logger.info(request.url)
AttributeError: 'WSGIRequest' object has no attribute 'url'
ERROR Internal Server Error: /
Traceback (most recent call last):
  File "/home/f/myproject/venv/lib/python3.5/site-packages/django/core/handlers/base.py", line 132, in get_response
    response = wrapped_callback(request, *callback_args, **callback_kwargs)
  File "/home/f/myproject/mybookstore/books/views.py", line 29, in index
    logger.info(request.url)
AttributeError: 'WSGIRequest' object has no attribute 'url'
ERROR Internal Server Error: /
Traceback (most recent call last):
  File "/home/f/myproject/venv/lib/python3.5/site-packages/django/core/handlers/base.py", line 132, in get_response
    response = wrapped_callback(request, *callback_args, **callback_kwargs)
  File "/home/f/myproject/mybookstore/books/views.py", line 29, in index
    logger.info(request.url)
AttributeError: 'WSGIRequest' object has no attribute 'url'
INFO b''
INFO b''
INFO b''
INFO b''
WARNING Not Found: /comment/comment/undefined
WARNING Not Found: /comment/comment/undefined
WARNING Not Found: /comment/comment/undefined
WARNING Not Found: /comment/comment/undefined
WARNING Not Found: /comment/comment/undefined
WARNING Not Found: /comment/comment/undefined
WARNING Not Found: /comment/comment/undefined
WARNING Not Found: /comment/comment/undefined
WARNING Not Found: /comment/comment/undefined
WARNING Not Found: /comment/comment/undefined
WARNING Not Found: /comment/comment/19
WARNING Not Found: /comment/comment/19
WARNING Not Found: /comment/comment/19
WARNING Not Found: /comment/comment/19
WARNING Not Found: /comment/comment/undefined
WARNING Not Found: /comment/comment/undefined
WARNING Not Found: /comment/comment/undefined
WARNING Not Found: /comment/comment/undefined
ERROR Internal Server Error: /books/article/
Traceback (most recent call last):
  File "/home/f/myproject/venv/lib/python3.5/site-packages/django/core/urlresolvers.py", line 565, in reverse
    extra, resolver = resolver.namespace_dict[ns]
KeyError: 'mybookstore.articles'

During handling of the above exception, another exception occurred:

Traceback (most recent call last):
  File "/home/f/myproject/venv/lib/python3.5/site-packages/django/template/defaulttags.py", line 501, in render
    current_app=current_app)
  File "/home/f/myproject/venv/lib/python3.5/site-packages/django/core/urlresolvers.py", line 575, in reverse
    key)
django.core.urlresolvers.NoReverseMatch: 'mybookstore.articles' is not a registered namespace

During handling of the above exception, another exception occurred:

Traceback (most recent call last):
  File "/home/f/myproject/venv/lib/python3.5/site-packages/django/core/handlers/base.py", line 132, in get_response
    response = wrapped_callback(request, *callback_args, **callback_kwargs)
  File "/home/f/myproject/mybookstore/books/views.py", line 132, in article
    return render(request, 'books/article.html')
  File "/home/f/myproject/venv/lib/python3.5/site-packages/django/shortcuts.py", line 67, in render
    template_name, context, request=request, using=using)
  File "/home/f/myproject/venv/lib/python3.5/site-packages/django/template/loader.py", line 99, in render_to_string
    return template.render(context, request)
  File "/home/f/myproject/venv/lib/python3.5/site-packages/django/template/backends/django.py", line 74, in render
    return self.template.render(context)
  File "/home/f/myproject/venv/lib/python3.5/site-packages/django/template/base.py", line 209, in render
    return self._render(context)
  File "/home/f/myproject/venv/lib/python3.5/site-packages/django/template/base.py", line 201, in _render
    return self.nodelist.render(context)
  File "/home/f/myproject/venv/lib/python3.5/site-packages/django/template/base.py", line 903, in render
    bit = self.render_node(node, context)
  File "/home/f/myproject/venv/lib/python3.5/site-packages/django/template/debug.py", line 79, in render_node
    return node.render(context)
  File "/home/f/myproject/venv/lib/python3.5/site-packages/django/template/loader_tags.py", line 135, in render
    return compiled_parent._render(context)
  File "/home/f/myproject/venv/lib/python3.5/site-packages/django/template/base.py", line 201, in _render
    return self.nodelist.render(context)
  File "/home/f/myproject/venv/lib/python3.5/site-packages/django/template/base.py", line 903, in render
    bit = self.render_node(node, context)
  File "/home/f/myproject/venv/lib/python3.5/site-packages/django/template/debug.py", line 79, in render_node
    return node.render(context)
  File "/home/f/myproject/venv/lib/python3.5/site-packages/django/template/loader_tags.py", line 65, in render
    result = block.nodelist.render(context)
  File "/home/f/myproject/venv/lib/python3.5/site-packages/django/template/base.py", line 903, in render
    bit = self.render_node(node, context)
  File "/home/f/myproject/venv/lib/python3.5/site-packages/django/template/debug.py", line 79, in render_node
    return node.render(context)
  File "/home/f/myproject/venv/lib/python3.5/site-packages/django/template/defaulttags.py", line 507, in render
    six.reraise(*exc_info)
  File "/home/f/myproject/venv/lib/python3.5/site-packages/django/utils/six.py", line 659, in reraise
    raise value
  File "/home/f/myproject/venv/lib/python3.5/site-packages/django/template/defaulttags.py", line 493, in render
    url = reverse(view_name, args=args, kwargs=kwargs, current_app=current_app)
  File "/home/f/myproject/venv/lib/python3.5/site-packages/django/core/urlresolvers.py", line 575, in reverse
    key)
django.core.urlresolvers.NoReverseMatch: 'articles' is not a registered namespace
ERROR Internal Server Error: /books/article/
Traceback (most recent call last):
  File "/home/f/myproject/venv/lib/python3.5/site-packages/django/core/urlresolvers.py", line 565, in reverse
    extra, resolver = resolver.namespace_dict[ns]
KeyError: 'mybookstore.articles'

During handling of the above exception, another exception occurred:

Traceback (most recent call last):
  File "/home/f/myproject/venv/lib/python3.5/site-packages/django/template/defaulttags.py", line 501, in render
    current_app=current_app)
  File "/home/f/myproject/venv/lib/python3.5/site-packages/django/core/urlresolvers.py", line 575, in reverse
    key)
django.core.urlresolvers.NoReverseMatch: 'mybookstore.articles' is not a registered namespace

During handling of the above exception, another exception occurred:

Traceback (most recent call last):
  File "/home/f/myproject/venv/lib/python3.5/site-packages/django/core/handlers/base.py", line 132, in get_response
    response = wrapped_callback(request, *callback_args, **callback_kwargs)
  File "/home/f/myproject/mybookstore/books/views.py", line 132, in article
    return render(request, 'books/article.html')
  File "/home/f/myproject/venv/lib/python3.5/site-packages/django/shortcuts.py", line 67, in render
    template_name, context, request=request, using=using)
  File "/home/f/myproject/venv/lib/python3.5/site-packages/django/template/loader.py", line 99, in render_to_string
    return template.render(context, request)
  File "/home/f/myproject/venv/lib/python3.5/site-packages/django/template/backends/django.py", line 74, in render
    return self.template.render(context)
  File "/home/f/myproject/venv/lib/python3.5/site-packages/django/template/base.py", line 209, in render
    return self._render(context)
  File "/home/f/myproject/venv/lib/python3.5/site-packages/django/template/base.py", line 201, in _render
    return self.nodelist.render(context)
  File "/home/f/myproject/venv/lib/python3.5/site-packages/django/template/base.py", line 903, in render
    bit = self.render_node(node, context)
  File "/home/f/myproject/venv/lib/python3.5/site-packages/django/template/debug.py", line 79, in render_node
    return node.render(context)
  File "/home/f/myproject/venv/lib/python3.5/site-packages/django/template/loader_tags.py", line 135, in render
    return compiled_parent._render(context)
  File "/home/f/myproject/venv/lib/python3.5/site-packages/django/template/base.py", line 201, in _render
    return self.nodelist.render(context)
  File "/home/f/myproject/venv/lib/python3.5/site-packages/django/template/base.py", line 903, in render
    bit = self.render_node(node, context)
  File "/home/f/myproject/venv/lib/python3.5/site-packages/django/template/debug.py", line 79, in render_node
    return node.render(context)
  File "/home/f/myproject/venv/lib/python3.5/site-packages/django/template/loader_tags.py", line 65, in render
    result = block.nodelist.render(context)
  File "/home/f/myproject/venv/lib/python3.5/site-packages/django/template/base.py", line 903, in render
    bit = self.render_node(node, context)
  File "/home/f/myproject/venv/lib/python3.5/site-packages/django/template/debug.py", line 79, in render_node
    return node.render(context)
  File "/home/f/myproject/venv/lib/python3.5/site-packages/django/template/defaulttags.py", line 507, in render
    six.reraise(*exc_info)
  File "/home/f/myproject/venv/lib/python3.5/site-packages/django/utils/six.py", line 659, in reraise
    raise value
  File "/home/f/myproject/venv/lib/python3.5/site-packages/django/template/defaulttags.py", line 493, in render
    url = reverse(view_name, args=args, kwargs=kwargs, current_app=current_app)
  File "/home/f/myproject/venv/lib/python3.5/site-packages/django/core/urlresolvers.py", line 575, in reverse
    key)
django.core.urlresolvers.NoReverseMatch: 'articles' is not a registered namespace
ERROR Internal Server Error: /books/article/
Traceback (most recent call last):
  File "/home/f/myproject/venv/lib/python3.5/site-packages/django/core/urlresolvers.py", line 565, in reverse
    extra, resolver = resolver.namespace_dict[ns]
KeyError: 'mybookstore.articles'

During handling of the above exception, another exception occurred:

Traceback (most recent call last):
  File "/home/f/myproject/venv/lib/python3.5/site-packages/django/template/defaulttags.py", line 501, in render
    current_app=current_app)
  File "/home/f/myproject/venv/lib/python3.5/site-packages/django/core/urlresolvers.py", line 575, in reverse
    key)
django.core.urlresolvers.NoReverseMatch: 'mybookstore.articles' is not a registered namespace

During handling of the above exception, another exception occurred:

Traceback (most recent call last):
  File "/home/f/myproject/venv/lib/python3.5/site-packages/django/core/handlers/base.py", line 132, in get_response
    response = wrapped_callback(request, *callback_args, **callback_kwargs)
  File "/home/f/myproject/mybookstore/books/views.py", line 132, in article
    return render(request, 'books/article.html')
  File "/home/f/myproject/venv/lib/python3.5/site-packages/django/shortcuts.py", line 67, in render
    template_name, context, request=request, using=using)
  File "/home/f/myproject/venv/lib/python3.5/site-packages/django/template/loader.py", line 99, in render_to_string
    return template.render(context, request)
  File "/home/f/myproject/venv/lib/python3.5/site-packages/django/template/backends/django.py", line 74, in render
    return self.template.render(context)
  File "/home/f/myproject/venv/lib/python3.5/site-packages/django/template/base.py", line 209, in render
    return self._render(context)
  File "/home/f/myproject/venv/lib/python3.5/site-packages/django/template/base.py", line 201, in _render
    return self.nodelist.render(context)
  File "/home/f/myproject/venv/lib/python3.5/site-packages/django/template/base.py", line 903, in render
    bit = self.render_node(node, context)
  File "/home/f/myproject/venv/lib/python3.5/site-packages/django/template/debug.py", line 79, in render_node
    return node.render(context)
  File "/home/f/myproject/venv/lib/python3.5/site-packages/django/template/loader_tags.py", line 135, in render
    return compiled_parent._render(context)
  File "/home/f/myproject/venv/lib/python3.5/site-packages/django/template/base.py", line 201, in _render
    return self.nodelist.render(context)
  File "/home/f/myproject/venv/lib/python3.5/site-packages/django/template/base.py", line 903, in render
    bit = self.render_node(node, context)
  File "/home/f/myproject/venv/lib/python3.5/site-packages/django/template/debug.py", line 79, in render_node
    return node.render(context)
  File "/home/f/myproject/venv/lib/python3.5/site-packages/django/template/loader_tags.py", line 65, in render
    result = block.nodelist.render(context)
  File "/home/f/myproject/venv/lib/python3.5/site-packages/django/template/base.py", line 903, in render
    bit = self.render_node(node, context)
  File "/home/f/myproject/venv/lib/python3.5/site-packages/django/template/debug.py", line 79, in render_node
    return node.render(context)
  File "/home/f/myproject/venv/lib/python3.5/site-packages/django/template/defaulttags.py", line 507, in render
    six.reraise(*exc_info)
  File "/home/f/myproject/venv/lib/python3.5/site-packages/django/utils/six.py", line 659, in reraise
    raise value
  File "/home/f/myproject/venv/lib/python3.5/site-packages/django/template/defaulttags.py", line 493, in render
    url = reverse(view_name, args=args, kwargs=kwargs, current_app=current_app)
  File "/home/f/myproject/venv/lib/python3.5/site-packages/django/core/urlresolvers.py", line 575, in reverse
    key)
django.core.urlresolvers.NoReverseMatch: 'articles' is not a registered namespace
ERROR Internal Server Error: /books/article/
Traceback (most recent call last):
  File "/home/f/myproject/venv/lib/python3.5/site-packages/django/core/urlresolvers.py", line 565, in reverse
    extra, resolver = resolver.namespace_dict[ns]
KeyError: 'mybookstore.articles'

During handling of the above exception, another exception occurred:

Traceback (most recent call last):
  File "/home/f/myproject/venv/lib/python3.5/site-packages/django/template/defaulttags.py", line 501, in render
    current_app=current_app)
  File "/home/f/myproject/venv/lib/python3.5/site-packages/django/core/urlresolvers.py", line 575, in reverse
    key)
django.core.urlresolvers.NoReverseMatch: 'mybookstore.articles' is not a registered namespace

During handling of the above exception, another exception occurred:

Traceback (most recent call last):
  File "/home/f/myproject/venv/lib/python3.5/site-packages/django/core/handlers/base.py", line 132, in get_response
    response = wrapped_callback(request, *callback_args, **callback_kwargs)
  File "/home/f/myproject/mybookstore/books/views.py", line 132, in article
    return render(request, 'books/article.html')
  File "/home/f/myproject/venv/lib/python3.5/site-packages/django/shortcuts.py", line 67, in render
    template_name, context, request=request, using=using)
  File "/home/f/myproject/venv/lib/python3.5/site-packages/django/template/loader.py", line 99, in render_to_string
    return template.render(context, request)
  File "/home/f/myproject/venv/lib/python3.5/site-packages/django/template/backends/django.py", line 74, in render
    return self.template.render(context)
  File "/home/f/myproject/venv/lib/python3.5/site-packages/django/template/base.py", line 209, in render
    return self._render(context)
  File "/home/f/myproject/venv/lib/python3.5/site-packages/django/template/base.py", line 201, in _render
    return self.nodelist.render(context)
  File "/home/f/myproject/venv/lib/python3.5/site-packages/django/template/base.py", line 903, in render
    bit = self.render_node(node, context)
  File "/home/f/myproject/venv/lib/python3.5/site-packages/django/template/debug.py", line 79, in render_node
    return node.render(context)
  File "/home/f/myproject/venv/lib/python3.5/site-packages/django/template/loader_tags.py", line 135, in render
    return compiled_parent._render(context)
  File "/home/f/myproject/venv/lib/python3.5/site-packages/django/template/base.py", line 201, in _render
    return self.nodelist.render(context)
  File "/home/f/myproject/venv/lib/python3.5/site-packages/django/template/base.py", line 903, in render
    bit = self.render_node(node, context)
  File "/home/f/myproject/venv/lib/python3.5/site-packages/django/template/debug.py", line 79, in render_node
    return node.render(context)
  File "/home/f/myproject/venv/lib/python3.5/site-packages/django/template/loader_tags.py", line 65, in render
    result = block.nodelist.render(context)
  File "/home/f/myproject/venv/lib/python3.5/site-packages/django/template/base.py", line 903, in render
    bit = self.render_node(node, context)
  File "/home/f/myproject/venv/lib/python3.5/site-packages/django/template/debug.py", line 79, in render_node
    return node.render(context)
  File "/home/f/myproject/venv/lib/python3.5/site-packages/django/template/defaulttags.py", line 507, in render
    six.reraise(*exc_info)
  File "/home/f/myproject/venv/lib/python3.5/site-packages/django/utils/six.py", line 659, in reraise
    raise value
  File "/home/f/myproject/venv/lib/python3.5/site-packages/django/template/defaulttags.py", line 493, in render
    url = reverse(view_name, args=args, kwargs=kwargs, current_app=current_app)
  File "/home/f/myproject/venv/lib/python3.5/site-packages/django/core/urlresolvers.py", line 575, in reverse
    key)
django.core.urlresolvers.NoReverseMatch: 'articles' is not a registered namespace
INFO <django.contrib.sessions.backends.cache.SessionStore object at 0x7f7711b6bd30>
INFO <django.contrib.sessions.backends.cache.SessionStore object at 0x7f7711b6bd30>
ERROR Internal Server Error: /books/detail/19/
Traceback (most recent call last):
  File "/home/f/myproject/venv/lib/python3.5/site-packages/django/core/urlresolvers.py", line 565, in reverse
    extra, resolver = resolver.namespace_dict[ns]
KeyError: 'mybookstore.books'

During handling of the above exception, another exception occurred:

Traceback (most recent call last):
  File "/home/f/myproject/venv/lib/python3.5/site-packages/django/template/defaulttags.py", line 501, in render
    current_app=current_app)
  File "/home/f/myproject/venv/lib/python3.5/site-packages/django/core/urlresolvers.py", line 575, in reverse
    key)
django.core.urlresolvers.NoReverseMatch: 'mybookstore.books' is not a registered namespace

During handling of the above exception, another exception occurred:

Traceback (most recent call last):
  File "/home/f/myproject/venv/lib/python3.5/site-packages/django/core/handlers/base.py", line 132, in get_response
    response = wrapped_callback(request, *callback_args, **callback_kwargs)
  File "/home/f/myproject/mybookstore/books/views.py", line 76, in detail
    return render(request, 'books/detail.html', context)
  File "/home/f/myproject/venv/lib/python3.5/site-packages/django/shortcuts.py", line 67, in render
    template_name, context, request=request, using=using)
  File "/home/f/myproject/venv/lib/python3.5/site-packages/django/template/loader.py", line 99, in render_to_string
    return template.render(context, request)
  File "/home/f/myproject/venv/lib/python3.5/site-packages/django/template/backends/django.py", line 74, in render
    return self.template.render(context)
  File "/home/f/myproject/venv/lib/python3.5/site-packages/django/template/base.py", line 209, in render
    return self._render(context)
  File "/home/f/myproject/venv/lib/python3.5/site-packages/django/template/base.py", line 201, in _render
    return self.nodelist.render(context)
  File "/home/f/myproject/venv/lib/python3.5/site-packages/django/template/base.py", line 903, in render
    bit = self.render_node(node, context)
  File "/home/f/myproject/venv/lib/python3.5/site-packages/django/template/debug.py", line 79, in render_node
    return node.render(context)
  File "/home/f/myproject/venv/lib/python3.5/site-packages/django/template/loader_tags.py", line 135, in render
    return compiled_parent._render(context)
  File "/home/f/myproject/venv/lib/python3.5/site-packages/django/template/base.py", line 201, in _render
    return self.nodelist.render(context)
  File "/home/f/myproject/venv/lib/python3.5/site-packages/django/template/base.py", line 903, in render
    bit = self.render_node(node, context)
  File "/home/f/myproject/venv/lib/python3.5/site-packages/django/template/debug.py", line 79, in render_node
    return node.render(context)
  File "/home/f/myproject/venv/lib/python3.5/site-packages/django/template/loader_tags.py", line 65, in render
    result = block.nodelist.render(context)
  File "/home/f/myproject/venv/lib/python3.5/site-packages/django/template/base.py", line 903, in render
    bit = self.render_node(node, context)
  File "/home/f/myproject/venv/lib/python3.5/site-packages/django/template/debug.py", line 79, in render_node
    return node.render(context)
  File "/home/f/myproject/venv/lib/python3.5/site-packages/django/template/defaulttags.py", line 507, in render
    six.reraise(*exc_info)
  File "/home/f/myproject/venv/lib/python3.5/site-packages/django/utils/six.py", line 659, in reraise
    raise value
  File "/home/f/myproject/venv/lib/python3.5/site-packages/django/template/defaulttags.py", line 493, in render
    url = reverse(view_name, args=args, kwargs=kwargs, current_app=current_app)
  File "/home/f/myproject/venv/lib/python3.5/site-packages/django/core/urlresolvers.py", line 579, in reverse
    return force_text(iri_to_uri(resolver._reverse_with_prefix(view, prefix, *args, **kwargs)))
  File "/home/f/myproject/venv/lib/python3.5/site-packages/django/core/urlresolvers.py", line 496, in _reverse_with_prefix
    (lookup_view_s, args, kwargs, len(patterns), patterns))
django.core.urlresolvers.NoReverseMatch: Reverse for 'article' with arguments '()' and keyword arguments '{}' not found. 1 pattern(s) tried: ['books/article/(?P<book_id>\\d+)/$']
ERROR Internal Server Error: /books/detail/19/
Traceback (most recent call last):
  File "/home/f/myproject/venv/lib/python3.5/site-packages/django/core/urlresolvers.py", line 565, in reverse
    extra, resolver = resolver.namespace_dict[ns]
KeyError: 'mybookstore.books'

During handling of the above exception, another exception occurred:

Traceback (most recent call last):
  File "/home/f/myproject/venv/lib/python3.5/site-packages/django/template/defaulttags.py", line 501, in render
    current_app=current_app)
  File "/home/f/myproject/venv/lib/python3.5/site-packages/django/core/urlresolvers.py", line 575, in reverse
    key)
django.core.urlresolvers.NoReverseMatch: 'mybookstore.books' is not a registered namespace

During handling of the above exception, another exception occurred:

Traceback (most recent call last):
  File "/home/f/myproject/venv/lib/python3.5/site-packages/django/core/handlers/base.py", line 132, in get_response
    response = wrapped_callback(request, *callback_args, **callback_kwargs)
  File "/home/f/myproject/mybookstore/books/views.py", line 76, in detail
    return render(request, 'books/detail.html', context)
  File "/home/f/myproject/venv/lib/python3.5/site-packages/django/shortcuts.py", line 67, in render
    template_name, context, request=request, using=using)
  File "/home/f/myproject/venv/lib/python3.5/site-packages/django/template/loader.py", line 99, in render_to_string
    return template.render(context, request)
  File "/home/f/myproject/venv/lib/python3.5/site-packages/django/template/backends/django.py", line 74, in render
    return self.template.render(context)
  File "/home/f/myproject/venv/lib/python3.5/site-packages/django/template/base.py", line 209, in render
    return self._render(context)
  File "/home/f/myproject/venv/lib/python3.5/site-packages/django/template/base.py", line 201, in _render
    return self.nodelist.render(context)
  File "/home/f/myproject/venv/lib/python3.5/site-packages/django/template/base.py", line 903, in render
    bit = self.render_node(node, context)
  File "/home/f/myproject/venv/lib/python3.5/site-packages/django/template/debug.py", line 79, in render_node
    return node.render(context)
  File "/home/f/myproject/venv/lib/python3.5/site-packages/django/template/loader_tags.py", line 135, in render
    return compiled_parent._render(context)
  File "/home/f/myproject/venv/lib/python3.5/site-packages/django/template/base.py", line 201, in _render
    return self.nodelist.render(context)
  File "/home/f/myproject/venv/lib/python3.5/site-packages/django/template/base.py", line 903, in render
    bit = self.render_node(node, context)
  File "/home/f/myproject/venv/lib/python3.5/site-packages/django/template/debug.py", line 79, in render_node
    return node.render(context)
  File "/home/f/myproject/venv/lib/python3.5/site-packages/django/template/loader_tags.py", line 65, in render
    result = block.nodelist.render(context)
  File "/home/f/myproject/venv/lib/python3.5/site-packages/django/template/base.py", line 903, in render
    bit = self.render_node(node, context)
  File "/home/f/myproject/venv/lib/python3.5/site-packages/django/template/debug.py", line 79, in render_node
    return node.render(context)
  File "/home/f/myproject/venv/lib/python3.5/site-packages/django/template/defaulttags.py", line 507, in render
    six.reraise(*exc_info)
  File "/home/f/myproject/venv/lib/python3.5/site-packages/django/utils/six.py", line 659, in reraise
    raise value
  File "/home/f/myproject/venv/lib/python3.5/site-packages/django/template/defaulttags.py", line 493, in render
    url = reverse(view_name, args=args, kwargs=kwargs, current_app=current_app)
  File "/home/f/myproject/venv/lib/python3.5/site-packages/django/core/urlresolvers.py", line 579, in reverse
    return force_text(iri_to_uri(resolver._reverse_with_prefix(view, prefix, *args, **kwargs)))
  File "/home/f/myproject/venv/lib/python3.5/site-packages/django/core/urlresolvers.py", line 496, in _reverse_with_prefix
    (lookup_view_s, args, kwargs, len(patterns), patterns))
django.core.urlresolvers.NoReverseMatch: Reverse for 'article' with arguments '()' and keyword arguments '{}' not found. 1 pattern(s) tried: ['books/article/(?P<book_id>\\d+)/$']
WARNING Not Found: /comment/comment/undefined
WARNING Not Found: /comment/comment/undefined
ERROR Internal Server Error: /books/article/19/
Traceback (most recent call last):
  File "/home/f/myproject/venv/lib/python3.5/site-packages/django/core/handlers/base.py", line 132, in get_response
    response = wrapped_callback(request, *callback_args, **callback_kwargs)
  File "/home/f/myproject/mybookstore/books/views.py", line 134, in article
    book = Books.objects.get_books_by_id(id=book_id)
TypeError: get_books_by_id() got an unexpected keyword argument 'id'
ERROR Internal Server Error: /books/article/19/
Traceback (most recent call last):
  File "/home/f/myproject/venv/lib/python3.5/site-packages/django/core/handlers/base.py", line 132, in get_response
    response = wrapped_callback(request, *callback_args, **callback_kwargs)
  File "/home/f/myproject/mybookstore/books/views.py", line 134, in article
    book = Books.objects.get_books_by_id(id=book_id)
TypeError: get_books_by_id() got an unexpected keyword argument 'id'
ERROR Internal Server Error: /books/article/19/
Traceback (most recent call last):
  File "/home/f/myproject/venv/lib/python3.5/site-packages/django/core/handlers/base.py", line 132, in get_response
    response = wrapped_callback(request, *callback_args, **callback_kwargs)
  File "/home/f/myproject/mybookstore/books/views.py", line 135, in article
    book = Books.objects.get_books_by_id(id=book_id)
TypeError: get_books_by_id() got an unexpected keyword argument 'id'
ERROR Internal Server Error: /books/article/19/
Traceback (most recent call last):
  File "/home/f/myproject/venv/lib/python3.5/site-packages/django/core/handlers/base.py", line 132, in get_response
    response = wrapped_callback(request, *callback_args, **callback_kwargs)
  File "/home/f/myproject/mybookstore/books/views.py", line 135, in article
    book = Books.objects.get_books_by_id(id=book_id)
TypeError: get_books_by_id() got an unexpected keyword argument 'id'
ERROR Internal Server Error: /books/article/19/
Traceback (most recent call last):
  File "/home/f/myproject/venv/lib/python3.5/site-packages/django/core/urlresolvers.py", line 565, in reverse
    extra, resolver = resolver.namespace_dict[ns]
KeyError: 'mybookstore.books'

During handling of the above exception, another exception occurred:

Traceback (most recent call last):
  File "/home/f/myproject/venv/lib/python3.5/site-packages/django/template/defaulttags.py", line 501, in render
    current_app=current_app)
  File "/home/f/myproject/venv/lib/python3.5/site-packages/django/core/urlresolvers.py", line 575, in reverse
    key)
django.core.urlresolvers.NoReverseMatch: 'mybookstore.books' is not a registered namespace

During handling of the above exception, another exception occurred:

Traceback (most recent call last):
  File "/home/f/myproject/venv/lib/python3.5/site-packages/django/core/handlers/base.py", line 132, in get_response
    response = wrapped_callback(request, *callback_args, **callback_kwargs)
  File "/home/f/myproject/mybookstore/books/views.py", line 135, in article
    return render(request, 'books/article.html', {'book': book})
  File "/home/f/myproject/venv/lib/python3.5/site-packages/django/shortcuts.py", line 67, in render
    template_name, context, request=request, using=using)
  File "/home/f/myproject/venv/lib/python3.5/site-packages/django/template/loader.py", line 99, in render_to_string
    return template.render(context, request)
  File "/home/f/myproject/venv/lib/python3.5/site-packages/django/template/backends/django.py", line 74, in render
    return self.template.render(context)
  File "/home/f/myproject/venv/lib/python3.5/site-packages/django/template/base.py", line 209, in render
    return self._render(context)
  File "/home/f/myproject/venv/lib/python3.5/site-packages/django/template/base.py", line 201, in _render
    return self.nodelist.render(context)
  File "/home/f/myproject/venv/lib/python3.5/site-packages/django/template/base.py", line 903, in render
    bit = self.render_node(node, context)
  File "/home/f/myproject/venv/lib/python3.5/site-packages/django/template/debug.py", line 79, in render_node
    return node.render(context)
  File "/home/f/myproject/venv/lib/python3.5/site-packages/django/template/loader_tags.py", line 135, in render
    return compiled_parent._render(context)
  File "/home/f/myproject/venv/lib/python3.5/site-packages/django/template/base.py", line 201, in _render
    return self.nodelist.render(context)
  File "/home/f/myproject/venv/lib/python3.5/site-packages/django/template/base.py", line 903, in render
    bit = self.render_node(node, context)
  File "/home/f/myproject/venv/lib/python3.5/site-packages/django/template/debug.py", line 79, in render_node
    return node.render(context)
  File "/home/f/myproject/venv/lib/python3.5/site-packages/django/template/loader_tags.py", line 65, in render
    result = block.nodelist.render(context)
  File "/home/f/myproject/venv/lib/python3.5/site-packages/django/template/base.py", line 903, in render
    bit = self.render_node(node, context)
  File "/home/f/myproject/venv/lib/python3.5/site-packages/django/template/debug.py", line 79, in render_node
    return node.render(context)
  File "/home/f/myproject/venv/lib/python3.5/site-packages/django/template/defaulttags.py", line 507, in render
    six.reraise(*exc_info)
  File "/home/f/myproject/venv/lib/python3.5/site-packages/django/utils/six.py", line 659, in reraise
    raise value
  File "/home/f/myproject/venv/lib/python3.5/site-packages/django/template/defaulttags.py", line 493, in render
    url = reverse(view_name, args=args, kwargs=kwargs, current_app=current_app)
  File "/home/f/myproject/venv/lib/python3.5/site-packages/django/core/urlresolvers.py", line 579, in reverse
    return force_text(iri_to_uri(resolver._reverse_with_prefix(view, prefix, *args, **kwargs)))
  File "/home/f/myproject/venv/lib/python3.5/site-packages/django/core/urlresolvers.py", line 496, in _reverse_with_prefix
    (lookup_view_s, args, kwargs, len(patterns), patterns))
django.core.urlresolvers.NoReverseMatch: Reverse for 'article' with arguments '()' and keyword arguments '{}' not found. 1 pattern(s) tried: ['books/article/(?P<book_id>\\d+)/$']
ERROR Internal Server Error: /books/article/19/
Traceback (most recent call last):
  File "/home/f/myproject/venv/lib/python3.5/site-packages/django/core/urlresolvers.py", line 565, in reverse
    extra, resolver = resolver.namespace_dict[ns]
KeyError: 'mybookstore.books'

During handling of the above exception, another exception occurred:

Traceback (most recent call last):
  File "/home/f/myproject/venv/lib/python3.5/site-packages/django/template/defaulttags.py", line 501, in render
    current_app=current_app)
  File "/home/f/myproject/venv/lib/python3.5/site-packages/django/core/urlresolvers.py", line 575, in reverse
    key)
django.core.urlresolvers.NoReverseMatch: 'mybookstore.books' is not a registered namespace

During handling of the above exception, another exception occurred:

Traceback (most recent call last):
  File "/home/f/myproject/venv/lib/python3.5/site-packages/django/core/handlers/base.py", line 132, in get_response
    response = wrapped_callback(request, *callback_args, **callback_kwargs)
  File "/home/f/myproject/mybookstore/books/views.py", line 135, in article
    return render(request, 'books/article.html', {'book': book})
  File "/home/f/myproject/venv/lib/python3.5/site-packages/django/shortcuts.py", line 67, in render
    template_name, context, request=request, using=using)
  File "/home/f/myproject/venv/lib/python3.5/site-packages/django/template/loader.py", line 99, in render_to_string
    return template.render(context, request)
  File "/home/f/myproject/venv/lib/python3.5/site-packages/django/template/backends/django.py", line 74, in render
    return self.template.render(context)
  File "/home/f/myproject/venv/lib/python3.5/site-packages/django/template/base.py", line 209, in render
    return self._render(context)
  File "/home/f/myproject/venv/lib/python3.5/site-packages/django/template/base.py", line 201, in _render
    return self.nodelist.render(context)
  File "/home/f/myproject/venv/lib/python3.5/site-packages/django/template/base.py", line 903, in render
    bit = self.render_node(node, context)
  File "/home/f/myproject/venv/lib/python3.5/site-packages/django/template/debug.py", line 79, in render_node
    return node.render(context)
  File "/home/f/myproject/venv/lib/python3.5/site-packages/django/template/loader_tags.py", line 135, in render
    return compiled_parent._render(context)
  File "/home/f/myproject/venv/lib/python3.5/site-packages/django/template/base.py", line 201, in _render
    return self.nodelist.render(context)
  File "/home/f/myproject/venv/lib/python3.5/site-packages/django/template/base.py", line 903, in render
    bit = self.render_node(node, context)
  File "/home/f/myproject/venv/lib/python3.5/site-packages/django/template/debug.py", line 79, in render_node
    return node.render(context)
  File "/home/f/myproject/venv/lib/python3.5/site-packages/django/template/loader_tags.py", line 65, in render
    result = block.nodelist.render(context)
  File "/home/f/myproject/venv/lib/python3.5/site-packages/django/template/base.py", line 903, in render
    bit = self.render_node(node, context)
  File "/home/f/myproject/venv/lib/python3.5/site-packages/django/template/debug.py", line 79, in render_node
    return node.render(context)
  File "/home/f/myproject/venv/lib/python3.5/site-packages/django/template/defaulttags.py", line 507, in render
    six.reraise(*exc_info)
  File "/home/f/myproject/venv/lib/python3.5/site-packages/django/utils/six.py", line 659, in reraise
    raise value
  File "/home/f/myproject/venv/lib/python3.5/site-packages/django/template/defaulttags.py", line 493, in render
    url = reverse(view_name, args=args, kwargs=kwargs, current_app=current_app)
  File "/home/f/myproject/venv/lib/python3.5/site-packages/django/core/urlresolvers.py", line 579, in reverse
    return force_text(iri_to_uri(resolver._reverse_with_prefix(view, prefix, *args, **kwargs)))
  File "/home/f/myproject/venv/lib/python3.5/site-packages/django/core/urlresolvers.py", line 496, in _reverse_with_prefix
    (lookup_view_s, args, kwargs, len(patterns), patterns))
django.core.urlresolvers.NoReverseMatch: Reverse for 'article' with arguments '()' and keyword arguments '{}' not found. 1 pattern(s) tried: ['books/article/(?P<book_id>\\d+)/$']
ERROR Internal Server Error: /books/article/19/
Traceback (most recent call last):
  File "/home/f/myproject/venv/lib/python3.5/site-packages/django/core/urlresolvers.py", line 565, in reverse
    extra, resolver = resolver.namespace_dict[ns]
KeyError: 'mybookstore.books'

During handling of the above exception, another exception occurred:

Traceback (most recent call last):
  File "/home/f/myproject/venv/lib/python3.5/site-packages/django/template/defaulttags.py", line 501, in render
    current_app=current_app)
  File "/home/f/myproject/venv/lib/python3.5/site-packages/django/core/urlresolvers.py", line 575, in reverse
    key)
django.core.urlresolvers.NoReverseMatch: 'mybookstore.books' is not a registered namespace

During handling of the above exception, another exception occurred:

Traceback (most recent call last):
  File "/home/f/myproject/venv/lib/python3.5/site-packages/django/core/handlers/base.py", line 132, in get_response
    response = wrapped_callback(request, *callback_args, **callback_kwargs)
  File "/home/f/myproject/mybookstore/books/views.py", line 135, in article
    return render(request, 'books/article.html', {'book': book})
  File "/home/f/myproject/venv/lib/python3.5/site-packages/django/shortcuts.py", line 67, in render
    template_name, context, request=request, using=using)
  File "/home/f/myproject/venv/lib/python3.5/site-packages/django/template/loader.py", line 99, in render_to_string
    return template.render(context, request)
  File "/home/f/myproject/venv/lib/python3.5/site-packages/django/template/backends/django.py", line 74, in render
    return self.template.render(context)
  File "/home/f/myproject/venv/lib/python3.5/site-packages/django/template/base.py", line 209, in render
    return self._render(context)
  File "/home/f/myproject/venv/lib/python3.5/site-packages/django/template/base.py", line 201, in _render
    return self.nodelist.render(context)
  File "/home/f/myproject/venv/lib/python3.5/site-packages/django/template/base.py", line 903, in render
    bit = self.render_node(node, context)
  File "/home/f/myproject/venv/lib/python3.5/site-packages/django/template/debug.py", line 79, in render_node
    return node.render(context)
  File "/home/f/myproject/venv/lib/python3.5/site-packages/django/template/loader_tags.py", line 135, in render
    return compiled_parent._render(context)
  File "/home/f/myproject/venv/lib/python3.5/site-packages/django/template/base.py", line 201, in _render
    return self.nodelist.render(context)
  File "/home/f/myproject/venv/lib/python3.5/site-packages/django/template/base.py", line 903, in render
    bit = self.render_node(node, context)
  File "/home/f/myproject/venv/lib/python3.5/site-packages/django/template/debug.py", line 79, in render_node
    return node.render(context)
  File "/home/f/myproject/venv/lib/python3.5/site-packages/django/template/loader_tags.py", line 65, in render
    result = block.nodelist.render(context)
  File "/home/f/myproject/venv/lib/python3.5/site-packages/django/template/base.py", line 903, in render
    bit = self.render_node(node, context)
  File "/home/f/myproject/venv/lib/python3.5/site-packages/django/template/debug.py", line 79, in render_node
    return node.render(context)
  File "/home/f/myproject/venv/lib/python3.5/site-packages/django/template/defaulttags.py", line 507, in render
    six.reraise(*exc_info)
  File "/home/f/myproject/venv/lib/python3.5/site-packages/django/utils/six.py", line 659, in reraise
    raise value
  File "/home/f/myproject/venv/lib/python3.5/site-packages/django/template/defaulttags.py", line 493, in render
    url = reverse(view_name, args=args, kwargs=kwargs, current_app=current_app)
  File "/home/f/myproject/venv/lib/python3.5/site-packages/django/core/urlresolvers.py", line 579, in reverse
    return force_text(iri_to_uri(resolver._reverse_with_prefix(view, prefix, *args, **kwargs)))
  File "/home/f/myproject/venv/lib/python3.5/site-packages/django/core/urlresolvers.py", line 496, in _reverse_with_prefix
    (lookup_view_s, args, kwargs, len(patterns), patterns))
django.core.urlresolvers.NoReverseMatch: Reverse for 'article' with arguments '()' and keyword arguments '{}' not found. 1 pattern(s) tried: ['books/article/(?P<book_id>\\d+)/$']
ERROR Internal Server Error: /books/article/19/
Traceback (most recent call last):
  File "/home/f/myproject/venv/lib/python3.5/site-packages/django/core/urlresolvers.py", line 565, in reverse
    extra, resolver = resolver.namespace_dict[ns]
KeyError: 'mybookstore.books'

During handling of the above exception, another exception occurred:

Traceback (most recent call last):
  File "/home/f/myproject/venv/lib/python3.5/site-packages/django/template/defaulttags.py", line 501, in render
    current_app=current_app)
  File "/home/f/myproject/venv/lib/python3.5/site-packages/django/core/urlresolvers.py", line 575, in reverse
    key)
django.core.urlresolvers.NoReverseMatch: 'mybookstore.books' is not a registered namespace

During handling of the above exception, another exception occurred:

Traceback (most recent call last):
  File "/home/f/myproject/venv/lib/python3.5/site-packages/django/core/handlers/base.py", line 132, in get_response
    response = wrapped_callback(request, *callback_args, **callback_kwargs)
  File "/home/f/myproject/mybookstore/books/views.py", line 135, in article
    return render(request, 'books/article.html', {'book': book})
  File "/home/f/myproject/venv/lib/python3.5/site-packages/django/shortcuts.py", line 67, in render
    template_name, context, request=request, using=using)
  File "/home/f/myproject/venv/lib/python3.5/site-packages/django/template/loader.py", line 99, in render_to_string
    return template.render(context, request)
  File "/home/f/myproject/venv/lib/python3.5/site-packages/django/template/backends/django.py", line 74, in render
    return self.template.render(context)
  File "/home/f/myproject/venv/lib/python3.5/site-packages/django/template/base.py", line 209, in render
    return self._render(context)
  File "/home/f/myproject/venv/lib/python3.5/site-packages/django/template/base.py", line 201, in _render
    return self.nodelist.render(context)
  File "/home/f/myproject/venv/lib/python3.5/site-packages/django/template/base.py", line 903, in render
    bit = self.render_node(node, context)
  File "/home/f/myproject/venv/lib/python3.5/site-packages/django/template/debug.py", line 79, in render_node
    return node.render(context)
  File "/home/f/myproject/venv/lib/python3.5/site-packages/django/template/loader_tags.py", line 135, in render
    return compiled_parent._render(context)
  File "/home/f/myproject/venv/lib/python3.5/site-packages/django/template/base.py", line 201, in _render
    return self.nodelist.render(context)
  File "/home/f/myproject/venv/lib/python3.5/site-packages/django/template/base.py", line 903, in render
    bit = self.render_node(node, context)
  File "/home/f/myproject/venv/lib/python3.5/site-packages/django/template/debug.py", line 79, in render_node
    return node.render(context)
  File "/home/f/myproject/venv/lib/python3.5/site-packages/django/template/loader_tags.py", line 65, in render
    result = block.nodelist.render(context)
  File "/home/f/myproject/venv/lib/python3.5/site-packages/django/template/base.py", line 903, in render
    bit = self.render_node(node, context)
  File "/home/f/myproject/venv/lib/python3.5/site-packages/django/template/debug.py", line 79, in render_node
    return node.render(context)
  File "/home/f/myproject/venv/lib/python3.5/site-packages/django/template/defaulttags.py", line 507, in render
    six.reraise(*exc_info)
  File "/home/f/myproject/venv/lib/python3.5/site-packages/django/utils/six.py", line 659, in reraise
    raise value
  File "/home/f/myproject/venv/lib/python3.5/site-packages/django/template/defaulttags.py", line 493, in render
    url = reverse(view_name, args=args, kwargs=kwargs, current_app=current_app)
  File "/home/f/myproject/venv/lib/python3.5/site-packages/django/core/urlresolvers.py", line 579, in reverse
    return force_text(iri_to_uri(resolver._reverse_with_prefix(view, prefix, *args, **kwargs)))
  File "/home/f/myproject/venv/lib/python3.5/site-packages/django/core/urlresolvers.py", line 496, in _reverse_with_prefix
    (lookup_view_s, args, kwargs, len(patterns), patterns))
django.core.urlresolvers.NoReverseMatch: Reverse for 'article' with arguments '()' and keyword arguments '{}' not found. 1 pattern(s) tried: ['books/article/(?P<book_id>\\d+)/$']
ERROR Internal Server Error: /books/article/19/
Traceback (most recent call last):
  File "/home/f/myproject/venv/lib/python3.5/site-packages/django/core/handlers/base.py", line 132, in get_response
    response = wrapped_callback(request, *callback_args, **callback_kwargs)
  File "/home/f/myproject/mybookstore/books/views.py", line 142, in article
    comment.user = request.session.get('passport_id')
  File "/home/f/myproject/venv/lib/python3.5/site-packages/django/db/models/fields/related.py", line 627, in __set__
    self.field.rel.to._meta.object_name,
ValueError: Cannot assign "6": "Comments.user" must be a "Passport" instance.
ERROR Internal Server Error: /books/article/19/
Traceback (most recent call last):
  File "/home/f/myproject/venv/lib/python3.5/site-packages/django/core/handlers/base.py", line 132, in get_response
    response = wrapped_callback(request, *callback_args, **callback_kwargs)
  File "/home/f/myproject/mybookstore/books/views.py", line 142, in article
    comment.user = request.session.get('passport_id')
  File "/home/f/myproject/venv/lib/python3.5/site-packages/django/db/models/fields/related.py", line 627, in __set__
    self.field.rel.to._meta.object_name,
ValueError: Cannot assign "6": "Comments.user" must be a "Passport" instance.
ERROR Internal Server Error: /books/article/19/
Traceback (most recent call last):
  File "/home/f/myproject/venv/lib/python3.5/site-packages/django/core/handlers/base.py", line 132, in get_response
    response = wrapped_callback(request, *callback_args, **callback_kwargs)
  File "/home/f/myproject/mybookstore/books/views.py", line 143, in article
    comment.book = int(book_id)
  File "/home/f/myproject/venv/lib/python3.5/site-packages/django/db/models/fields/related.py", line 627, in __set__
    self.field.rel.to._meta.object_name,
ValueError: Cannot assign "19": "Comments.book" must be a "Books" instance.
ERROR Internal Server Error: /books/article/19/
Traceback (most recent call last):
  File "/home/f/myproject/venv/lib/python3.5/site-packages/django/core/handlers/base.py", line 132, in get_response
    response = wrapped_callback(request, *callback_args, **callback_kwargs)
  File "/home/f/myproject/mybookstore/books/views.py", line 143, in article
    comment.book = int(book_id)
  File "/home/f/myproject/venv/lib/python3.5/site-packages/django/db/models/fields/related.py", line 627, in __set__
    self.field.rel.to._meta.object_name,
ValueError: Cannot assign "19": "Comments.book" must be a "Books" instance.
ERROR Internal Server Error: /books/article/19/
Traceback (most recent call last):
  File "/home/f/myproject/venv/lib/python3.5/site-packages/django/db/backends/utils.py", line 64, in execute
    return self.cursor.execute(sql, params)
  File "/home/f/myproject/venv/lib/python3.5/site-packages/django/db/backends/mysql/base.py", line 124, in execute
    return self.cursor.execute(query, args)
  File "/home/f/myproject/venv/lib/python3.5/site-packages/pymysql/cursors.py", line 166, in execute
    result = self._query(query)
  File "/home/f/myproject/venv/lib/python3.5/site-packages/pymysql/cursors.py", line 322, in _query
    conn.query(q)
  File "/home/f/myproject/venv/lib/python3.5/site-packages/pymysql/connections.py", line 856, in query
    self._affected_rows = self._read_query_result(unbuffered=unbuffered)
  File "/home/f/myproject/venv/lib/python3.5/site-packages/pymysql/connections.py", line 1057, in _read_query_result
    result.read()
  File "/home/f/myproject/venv/lib/python3.5/site-packages/pymysql/connections.py", line 1340, in read
    first_packet = self.connection._read_packet()
  File "/home/f/myproject/venv/lib/python3.5/site-packages/pymysql/connections.py", line 1014, in _read_packet
    packet.check_error()
  File "/home/f/myproject/venv/lib/python3.5/site-packages/pymysql/connections.py", line 393, in check_error
    err.raise_mysql_exception(self._data)
  File "/home/f/myproject/venv/lib/python3.5/site-packages/pymysql/err.py", line 107, in raise_mysql_exception
    raise errorclass(errno, errval)
pymysql.err.IntegrityError: (1048, "Column 'title' cannot be null")

The above exception was the direct cause of the following exception:

Traceback (most recent call last):
  File "/home/f/myproject/venv/lib/python3.5/site-packages/django/core/handlers/base.py", line 132, in get_response
    response = wrapped_callback(request, *callback_args, **callback_kwargs)
  File "/home/f/myproject/mybookstore/books/views.py", line 146, in article
    comment.save()
  File "/home/f/myproject/venv/lib/python3.5/site-packages/django/db/models/base.py", line 710, in save
    force_update=force_update, update_fields=update_fields)
  File "/home/f/myproject/venv/lib/python3.5/site-packages/django/db/models/base.py", line 738, in save_base
    updated = self._save_table(raw, cls, force_insert, force_update, using, update_fields)
  File "/home/f/myproject/venv/lib/python3.5/site-packages/django/db/models/base.py", line 822, in _save_table
    result = self._do_insert(cls._base_manager, using, fields, update_pk, raw)
  File "/home/f/myproject/venv/lib/python3.5/site-packages/django/db/models/base.py", line 861, in _do_insert
    using=using, raw=raw)
  File "/home/f/myproject/venv/lib/python3.5/site-packages/django/db/models/manager.py", line 127, in manager_method
    return getattr(self.get_queryset(), name)(*args, **kwargs)
  File "/home/f/myproject/venv/lib/python3.5/site-packages/django/db/models/query.py", line 920, in _insert
    return query.get_compiler(using=using).execute_sql(return_id)
  File "/home/f/myproject/venv/lib/python3.5/site-packages/django/db/models/sql/compiler.py", line 974, in execute_sql
    cursor.execute(sql, params)
  File "/home/f/myproject/venv/lib/python3.5/site-packages/django/db/backends/utils.py", line 79, in execute
    return super(CursorDebugWrapper, self).execute(sql, params)
  File "/home/f/myproject/venv/lib/python3.5/site-packages/django/db/backends/utils.py", line 64, in execute
    return self.cursor.execute(sql, params)
  File "/home/f/myproject/venv/lib/python3.5/site-packages/django/db/utils.py", line 97, in __exit__
    six.reraise(dj_exc_type, dj_exc_value, traceback)
  File "/home/f/myproject/venv/lib/python3.5/site-packages/django/utils/six.py", line 658, in reraise
    raise value.with_traceback(tb)
  File "/home/f/myproject/venv/lib/python3.5/site-packages/django/db/backends/utils.py", line 64, in execute
    return self.cursor.execute(sql, params)
  File "/home/f/myproject/venv/lib/python3.5/site-packages/django/db/backends/mysql/base.py", line 124, in execute
    return self.cursor.execute(query, args)
  File "/home/f/myproject/venv/lib/python3.5/site-packages/pymysql/cursors.py", line 166, in execute
    result = self._query(query)
  File "/home/f/myproject/venv/lib/python3.5/site-packages/pymysql/cursors.py", line 322, in _query
    conn.query(q)
  File "/home/f/myproject/venv/lib/python3.5/site-packages/pymysql/connections.py", line 856, in query
    self._affected_rows = self._read_query_result(unbuffered=unbuffered)
  File "/home/f/myproject/venv/lib/python3.5/site-packages/pymysql/connections.py", line 1057, in _read_query_result
    result.read()
  File "/home/f/myproject/venv/lib/python3.5/site-packages/pymysql/connections.py", line 1340, in read
    first_packet = self.connection._read_packet()
  File "/home/f/myproject/venv/lib/python3.5/site-packages/pymysql/connections.py", line 1014, in _read_packet
    packet.check_error()
  File "/home/f/myproject/venv/lib/python3.5/site-packages/pymysql/connections.py", line 393, in check_error
    err.raise_mysql_exception(self._data)
  File "/home/f/myproject/venv/lib/python3.5/site-packages/pymysql/err.py", line 107, in raise_mysql_exception
    raise errorclass(errno, errval)
django.db.utils.IntegrityError: (1048, "Column 'title' cannot be null")
ERROR Internal Server Error: /books/article/19/
Traceback (most recent call last):
  File "/home/f/myproject/venv/lib/python3.5/site-packages/django/db/backends/utils.py", line 64, in execute
    return self.cursor.execute(sql, params)
  File "/home/f/myproject/venv/lib/python3.5/site-packages/django/db/backends/mysql/base.py", line 124, in execute
    return self.cursor.execute(query, args)
  File "/home/f/myproject/venv/lib/python3.5/site-packages/pymysql/cursors.py", line 166, in execute
    result = self._query(query)
  File "/home/f/myproject/venv/lib/python3.5/site-packages/pymysql/cursors.py", line 322, in _query
    conn.query(q)
  File "/home/f/myproject/venv/lib/python3.5/site-packages/pymysql/connections.py", line 856, in query
    self._affected_rows = self._read_query_result(unbuffered=unbuffered)
  File "/home/f/myproject/venv/lib/python3.5/site-packages/pymysql/connections.py", line 1057, in _read_query_result
    result.read()
  File "/home/f/myproject/venv/lib/python3.5/site-packages/pymysql/connections.py", line 1340, in read
    first_packet = self.connection._read_packet()
  File "/home/f/myproject/venv/lib/python3.5/site-packages/pymysql/connections.py", line 1014, in _read_packet
    packet.check_error()
  File "/home/f/myproject/venv/lib/python3.5/site-packages/pymysql/connections.py", line 393, in check_error
    err.raise_mysql_exception(self._data)
  File "/home/f/myproject/venv/lib/python3.5/site-packages/pymysql/err.py", line 107, in raise_mysql_exception
    raise errorclass(errno, errval)
pymysql.err.IntegrityError: (1048, "Column 'title' cannot be null")

The above exception was the direct cause of the following exception:

Traceback (most recent call last):
  File "/home/f/myproject/venv/lib/python3.5/site-packages/django/core/handlers/base.py", line 132, in get_response
    response = wrapped_callback(request, *callback_args, **callback_kwargs)
  File "/home/f/myproject/mybookstore/books/views.py", line 146, in article
    comment.save()
  File "/home/f/myproject/venv/lib/python3.5/site-packages/django/db/models/base.py", line 710, in save
    force_update=force_update, update_fields=update_fields)
  File "/home/f/myproject/venv/lib/python3.5/site-packages/django/db/models/base.py", line 738, in save_base
    updated = self._save_table(raw, cls, force_insert, force_update, using, update_fields)
  File "/home/f/myproject/venv/lib/python3.5/site-packages/django/db/models/base.py", line 822, in _save_table
    result = self._do_insert(cls._base_manager, using, fields, update_pk, raw)
  File "/home/f/myproject/venv/lib/python3.5/site-packages/django/db/models/base.py", line 861, in _do_insert
    using=using, raw=raw)
  File "/home/f/myproject/venv/lib/python3.5/site-packages/django/db/models/manager.py", line 127, in manager_method
    return getattr(self.get_queryset(), name)(*args, **kwargs)
  File "/home/f/myproject/venv/lib/python3.5/site-packages/django/db/models/query.py", line 920, in _insert
    return query.get_compiler(using=using).execute_sql(return_id)
  File "/home/f/myproject/venv/lib/python3.5/site-packages/django/db/models/sql/compiler.py", line 974, in execute_sql
    cursor.execute(sql, params)
  File "/home/f/myproject/venv/lib/python3.5/site-packages/django/db/backends/utils.py", line 79, in execute
    return super(CursorDebugWrapper, self).execute(sql, params)
  File "/home/f/myproject/venv/lib/python3.5/site-packages/django/db/backends/utils.py", line 64, in execute
    return self.cursor.execute(sql, params)
  File "/home/f/myproject/venv/lib/python3.5/site-packages/django/db/utils.py", line 97, in __exit__
    six.reraise(dj_exc_type, dj_exc_value, traceback)
  File "/home/f/myproject/venv/lib/python3.5/site-packages/django/utils/six.py", line 658, in reraise
    raise value.with_traceback(tb)
  File "/home/f/myproject/venv/lib/python3.5/site-packages/django/db/backends/utils.py", line 64, in execute
    return self.cursor.execute(sql, params)
  File "/home/f/myproject/venv/lib/python3.5/site-packages/django/db/backends/mysql/base.py", line 124, in execute
    return self.cursor.execute(query, args)
  File "/home/f/myproject/venv/lib/python3.5/site-packages/pymysql/cursors.py", line 166, in execute
    result = self._query(query)
  File "/home/f/myproject/venv/lib/python3.5/site-packages/pymysql/cursors.py", line 322, in _query
    conn.query(q)
  File "/home/f/myproject/venv/lib/python3.5/site-packages/pymysql/connections.py", line 856, in query
    self._affected_rows = self._read_query_result(unbuffered=unbuffered)
  File "/home/f/myproject/venv/lib/python3.5/site-packages/pymysql/connections.py", line 1057, in _read_query_result
    result.read()
  File "/home/f/myproject/venv/lib/python3.5/site-packages/pymysql/connections.py", line 1340, in read
    first_packet = self.connection._read_packet()
  File "/home/f/myproject/venv/lib/python3.5/site-packages/pymysql/connections.py", line 1014, in _read_packet
    packet.check_error()
  File "/home/f/myproject/venv/lib/python3.5/site-packages/pymysql/connections.py", line 393, in check_error
    err.raise_mysql_exception(self._data)
  File "/home/f/myproject/venv/lib/python3.5/site-packages/pymysql/err.py", line 107, in raise_mysql_exception
    raise errorclass(errno, errval)
django.db.utils.IntegrityError: (1048, "Column 'title' cannot be null")
ERROR Internal Server Error: /books/article/19/
Traceback (most recent call last):
  File "/home/f/myproject/venv/lib/python3.5/site-packages/django/db/backends/utils.py", line 64, in execute
    return self.cursor.execute(sql, params)
  File "/home/f/myproject/venv/lib/python3.5/site-packages/django/db/backends/mysql/base.py", line 124, in execute
    return self.cursor.execute(query, args)
  File "/home/f/myproject/venv/lib/python3.5/site-packages/pymysql/cursors.py", line 166, in execute
    result = self._query(query)
  File "/home/f/myproject/venv/lib/python3.5/site-packages/pymysql/cursors.py", line 322, in _query
    conn.query(q)
  File "/home/f/myproject/venv/lib/python3.5/site-packages/pymysql/connections.py", line 856, in query
    self._affected_rows = self._read_query_result(unbuffered=unbuffered)
  File "/home/f/myproject/venv/lib/python3.5/site-packages/pymysql/connections.py", line 1057, in _read_query_result
    result.read()
  File "/home/f/myproject/venv/lib/python3.5/site-packages/pymysql/connections.py", line 1340, in read
    first_packet = self.connection._read_packet()
  File "/home/f/myproject/venv/lib/python3.5/site-packages/pymysql/connections.py", line 1014, in _read_packet
    packet.check_error()
  File "/home/f/myproject/venv/lib/python3.5/site-packages/pymysql/connections.py", line 393, in check_error
    err.raise_mysql_exception(self._data)
  File "/home/f/myproject/venv/lib/python3.5/site-packages/pymysql/err.py", line 107, in raise_mysql_exception
    raise errorclass(errno, errval)
pymysql.err.IntegrityError: (1048, "Column 'title' cannot be null")

The above exception was the direct cause of the following exception:

Traceback (most recent call last):
  File "/home/f/myproject/venv/lib/python3.5/site-packages/django/core/handlers/base.py", line 132, in get_response
    response = wrapped_callback(request, *callback_args, **callback_kwargs)
  File "/home/f/myproject/mybookstore/books/views.py", line 146, in article
    comment.save()
  File "/home/f/myproject/venv/lib/python3.5/site-packages/django/db/models/base.py", line 710, in save
    force_update=force_update, update_fields=update_fields)
  File "/home/f/myproject/venv/lib/python3.5/site-packages/django/db/models/base.py", line 738, in save_base
    updated = self._save_table(raw, cls, force_insert, force_update, using, update_fields)
  File "/home/f/myproject/venv/lib/python3.5/site-packages/django/db/models/base.py", line 822, in _save_table
    result = self._do_insert(cls._base_manager, using, fields, update_pk, raw)
  File "/home/f/myproject/venv/lib/python3.5/site-packages/django/db/models/base.py", line 861, in _do_insert
    using=using, raw=raw)
  File "/home/f/myproject/venv/lib/python3.5/site-packages/django/db/models/manager.py", line 127, in manager_method
    return getattr(self.get_queryset(), name)(*args, **kwargs)
  File "/home/f/myproject/venv/lib/python3.5/site-packages/django/db/models/query.py", line 920, in _insert
    return query.get_compiler(using=using).execute_sql(return_id)
  File "/home/f/myproject/venv/lib/python3.5/site-packages/django/db/models/sql/compiler.py", line 974, in execute_sql
    cursor.execute(sql, params)
  File "/home/f/myproject/venv/lib/python3.5/site-packages/django/db/backends/utils.py", line 79, in execute
    return super(CursorDebugWrapper, self).execute(sql, params)
  File "/home/f/myproject/venv/lib/python3.5/site-packages/django/db/backends/utils.py", line 64, in execute
    return self.cursor.execute(sql, params)
  File "/home/f/myproject/venv/lib/python3.5/site-packages/django/db/utils.py", line 97, in __exit__
    six.reraise(dj_exc_type, dj_exc_value, traceback)
  File "/home/f/myproject/venv/lib/python3.5/site-packages/django/utils/six.py", line 658, in reraise
    raise value.with_traceback(tb)
  File "/home/f/myproject/venv/lib/python3.5/site-packages/django/db/backends/utils.py", line 64, in execute
    return self.cursor.execute(sql, params)
  File "/home/f/myproject/venv/lib/python3.5/site-packages/django/db/backends/mysql/base.py", line 124, in execute
    return self.cursor.execute(query, args)
  File "/home/f/myproject/venv/lib/python3.5/site-packages/pymysql/cursors.py", line 166, in execute
    result = self._query(query)
  File "/home/f/myproject/venv/lib/python3.5/site-packages/pymysql/cursors.py", line 322, in _query
    conn.query(q)
  File "/home/f/myproject/venv/lib/python3.5/site-packages/pymysql/connections.py", line 856, in query
    self._affected_rows = self._read_query_result(unbuffered=unbuffered)
  File "/home/f/myproject/venv/lib/python3.5/site-packages/pymysql/connections.py", line 1057, in _read_query_result
    result.read()
  File "/home/f/myproject/venv/lib/python3.5/site-packages/pymysql/connections.py", line 1340, in read
    first_packet = self.connection._read_packet()
  File "/home/f/myproject/venv/lib/python3.5/site-packages/pymysql/connections.py", line 1014, in _read_packet
    packet.check_error()
  File "/home/f/myproject/venv/lib/python3.5/site-packages/pymysql/connections.py", line 393, in check_error
    err.raise_mysql_exception(self._data)
  File "/home/f/myproject/venv/lib/python3.5/site-packages/pymysql/err.py", line 107, in raise_mysql_exception
    raise errorclass(errno, errval)
django.db.utils.IntegrityError: (1048, "Column 'title' cannot be null")
ERROR Internal Server Error: /books/article/19/
Traceback (most recent call last):
  File "/home/f/myproject/venv/lib/python3.5/site-packages/django/db/backends/utils.py", line 64, in execute
    return self.cursor.execute(sql, params)
  File "/home/f/myproject/venv/lib/python3.5/site-packages/django/db/backends/mysql/base.py", line 124, in execute
    return self.cursor.execute(query, args)
  File "/home/f/myproject/venv/lib/python3.5/site-packages/pymysql/cursors.py", line 166, in execute
    result = self._query(query)
  File "/home/f/myproject/venv/lib/python3.5/site-packages/pymysql/cursors.py", line 322, in _query
    conn.query(q)
  File "/home/f/myproject/venv/lib/python3.5/site-packages/pymysql/connections.py", line 856, in query
    self._affected_rows = self._read_query_result(unbuffered=unbuffered)
  File "/home/f/myproject/venv/lib/python3.5/site-packages/pymysql/connections.py", line 1057, in _read_query_result
    result.read()
  File "/home/f/myproject/venv/lib/python3.5/site-packages/pymysql/connections.py", line 1340, in read
    first_packet = self.connection._read_packet()
  File "/home/f/myproject/venv/lib/python3.5/site-packages/pymysql/connections.py", line 1014, in _read_packet
    packet.check_error()
  File "/home/f/myproject/venv/lib/python3.5/site-packages/pymysql/connections.py", line 393, in check_error
    err.raise_mysql_exception(self._data)
  File "/home/f/myproject/venv/lib/python3.5/site-packages/pymysql/err.py", line 107, in raise_mysql_exception
    raise errorclass(errno, errval)
pymysql.err.IntegrityError: (1048, "Column 'title' cannot be null")

The above exception was the direct cause of the following exception:

Traceback (most recent call last):
  File "/home/f/myproject/venv/lib/python3.5/site-packages/django/core/handlers/base.py", line 132, in get_response
    response = wrapped_callback(request, *callback_args, **callback_kwargs)
  File "/home/f/myproject/mybookstore/books/views.py", line 146, in article
    comment.save()
  File "/home/f/myproject/venv/lib/python3.5/site-packages/django/db/models/base.py", line 710, in save
    force_update=force_update, update_fields=update_fields)
  File "/home/f/myproject/venv/lib/python3.5/site-packages/django/db/models/base.py", line 738, in save_base
    updated = self._save_table(raw, cls, force_insert, force_update, using, update_fields)
  File "/home/f/myproject/venv/lib/python3.5/site-packages/django/db/models/base.py", line 822, in _save_table
    result = self._do_insert(cls._base_manager, using, fields, update_pk, raw)
  File "/home/f/myproject/venv/lib/python3.5/site-packages/django/db/models/base.py", line 861, in _do_insert
    using=using, raw=raw)
  File "/home/f/myproject/venv/lib/python3.5/site-packages/django/db/models/manager.py", line 127, in manager_method
    return getattr(self.get_queryset(), name)(*args, **kwargs)
  File "/home/f/myproject/venv/lib/python3.5/site-packages/django/db/models/query.py", line 920, in _insert
    return query.get_compiler(using=using).execute_sql(return_id)
  File "/home/f/myproject/venv/lib/python3.5/site-packages/django/db/models/sql/compiler.py", line 974, in execute_sql
    cursor.execute(sql, params)
  File "/home/f/myproject/venv/lib/python3.5/site-packages/django/db/backends/utils.py", line 79, in execute
    return super(CursorDebugWrapper, self).execute(sql, params)
  File "/home/f/myproject/venv/lib/python3.5/site-packages/django/db/backends/utils.py", line 64, in execute
    return self.cursor.execute(sql, params)
  File "/home/f/myproject/venv/lib/python3.5/site-packages/django/db/utils.py", line 97, in __exit__
    six.reraise(dj_exc_type, dj_exc_value, traceback)
  File "/home/f/myproject/venv/lib/python3.5/site-packages/django/utils/six.py", line 658, in reraise
    raise value.with_traceback(tb)
  File "/home/f/myproject/venv/lib/python3.5/site-packages/django/db/backends/utils.py", line 64, in execute
    return self.cursor.execute(sql, params)
  File "/home/f/myproject/venv/lib/python3.5/site-packages/django/db/backends/mysql/base.py", line 124, in execute
    return self.cursor.execute(query, args)
  File "/home/f/myproject/venv/lib/python3.5/site-packages/pymysql/cursors.py", line 166, in execute
    result = self._query(query)
  File "/home/f/myproject/venv/lib/python3.5/site-packages/pymysql/cursors.py", line 322, in _query
    conn.query(q)
  File "/home/f/myproject/venv/lib/python3.5/site-packages/pymysql/connections.py", line 856, in query
    self._affected_rows = self._read_query_result(unbuffered=unbuffered)
  File "/home/f/myproject/venv/lib/python3.5/site-packages/pymysql/connections.py", line 1057, in _read_query_result
    result.read()
  File "/home/f/myproject/venv/lib/python3.5/site-packages/pymysql/connections.py", line 1340, in read
    first_packet = self.connection._read_packet()
  File "/home/f/myproject/venv/lib/python3.5/site-packages/pymysql/connections.py", line 1014, in _read_packet
    packet.check_error()
  File "/home/f/myproject/venv/lib/python3.5/site-packages/pymysql/connections.py", line 393, in check_error
    err.raise_mysql_exception(self._data)
  File "/home/f/myproject/venv/lib/python3.5/site-packages/pymysql/err.py", line 107, in raise_mysql_exception
    raise errorclass(errno, errval)
django.db.utils.IntegrityError: (1048, "Column 'title' cannot be null")
INFO <django.contrib.sessions.backends.cache.SessionStore object at 0x7fce146d9748>
INFO <django.contrib.sessions.backends.cache.SessionStore object at 0x7fce146d9748>
INFO <django.contrib.sessions.backends.cache.SessionStore object at 0x7f26543afdd8>
INFO <django.contrib.sessions.backends.cache.SessionStore object at 0x7f26543afdd8>
WARNING Not Found: /comment/comment/undefined
WARNING Not Found: /comment/comment/undefined
ERROR Internal Server Error: /books/article/19/
Traceback (most recent call last):
  File "/home/f/myproject/venv/lib/python3.5/site-packages/django/core/handlers/base.py", line 151, in get_response
    % (callback.__module__, view_name))
ValueError: The view books.views.article didn't return an HttpResponse object. It returned None instead.
ERROR Internal Server Error: /books/article/19/
Traceback (most recent call last):
  File "/home/f/myproject/venv/lib/python3.5/site-packages/django/core/handlers/base.py", line 151, in get_response
    % (callback.__module__, view_name))
ValueError: The view books.views.article didn't return an HttpResponse object. It returned None instead.
ERROR Internal Server Error: /books/article/19/
Traceback (most recent call last):
  File "/home/f/myproject/venv/lib/python3.5/site-packages/django/core/handlers/base.py", line 151, in get_response
    % (callback.__module__, view_name))
ValueError: The view books.views.article didn't return an HttpResponse object. It returned None instead.
ERROR Internal Server Error: /books/article/19/
Traceback (most recent call last):
  File "/home/f/myproject/venv/lib/python3.5/site-packages/django/core/handlers/base.py", line 151, in get_response
    % (callback.__module__, view_name))
ValueError: The view books.views.article didn't return an HttpResponse object. It returned None instead.
INFO <django.contrib.sessions.backends.cache.SessionStore object at 0x7feb29d46dd8>
INFO <django.contrib.sessions.backends.cache.SessionStore object at 0x7feb29d46dd8>
INFO <django.contrib.sessions.backends.cache.SessionStore object at 0x7feb1a8343c8>
INFO <django.contrib.sessions.backends.cache.SessionStore object at 0x7feb1a8343c8>
WARNING Not Found: /comment/comment/undefined
WARNING Not Found: /comment/comment/undefined
ERROR Internal Server Error: /books/article/4/
Traceback (most recent call last):
  File "/home/f/myproject/venv/lib/python3.5/site-packages/django/db/backends/utils.py", line 64, in execute
    return self.cursor.execute(sql, params)
  File "/home/f/myproject/venv/lib/python3.5/site-packages/django/db/backends/mysql/base.py", line 124, in execute
    return self.cursor.execute(query, args)
  File "/home/f/myproject/venv/lib/python3.5/site-packages/pymysql/cursors.py", line 166, in execute
    result = self._query(query)
  File "/home/f/myproject/venv/lib/python3.5/site-packages/pymysql/cursors.py", line 322, in _query
    conn.query(q)
  File "/home/f/myproject/venv/lib/python3.5/site-packages/pymysql/connections.py", line 856, in query
    self._affected_rows = self._read_query_result(unbuffered=unbuffered)
  File "/home/f/myproject/venv/lib/python3.5/site-packages/pymysql/connections.py", line 1057, in _read_query_result
    result.read()
  File "/home/f/myproject/venv/lib/python3.5/site-packages/pymysql/connections.py", line 1340, in read
    first_packet = self.connection._read_packet()
  File "/home/f/myproject/venv/lib/python3.5/site-packages/pymysql/connections.py", line 1014, in _read_packet
    packet.check_error()
  File "/home/f/myproject/venv/lib/python3.5/site-packages/pymysql/connections.py", line 393, in check_error
    err.raise_mysql_exception(self._data)
  File "/home/f/myproject/venv/lib/python3.5/site-packages/pymysql/err.py", line 107, in raise_mysql_exception
    raise errorclass(errno, errval)
pymysql.err.IntegrityError: (1048, "Column 'title' cannot be null")

The above exception was the direct cause of the following exception:

Traceback (most recent call last):
  File "/home/f/myproject/venv/lib/python3.5/site-packages/django/core/handlers/base.py", line 132, in get_response
    response = wrapped_callback(request, *callback_args, **callback_kwargs)
  File "/home/f/myproject/mybookstore/books/views.py", line 147, in article
    comment.save()
  File "/home/f/myproject/venv/lib/python3.5/site-packages/django/db/models/base.py", line 710, in save
    force_update=force_update, update_fields=update_fields)
  File "/home/f/myproject/venv/lib/python3.5/site-packages/django/db/models/base.py", line 738, in save_base
    updated = self._save_table(raw, cls, force_insert, force_update, using, update_fields)
  File "/home/f/myproject/venv/lib/python3.5/site-packages/django/db/models/base.py", line 822, in _save_table
    result = self._do_insert(cls._base_manager, using, fields, update_pk, raw)
  File "/home/f/myproject/venv/lib/python3.5/site-packages/django/db/models/base.py", line 861, in _do_insert
    using=using, raw=raw)
  File "/home/f/myproject/venv/lib/python3.5/site-packages/django/db/models/manager.py", line 127, in manager_method
    return getattr(self.get_queryset(), name)(*args, **kwargs)
  File "/home/f/myproject/venv/lib/python3.5/site-packages/django/db/models/query.py", line 920, in _insert
    return query.get_compiler(using=using).execute_sql(return_id)
  File "/home/f/myproject/venv/lib/python3.5/site-packages/django/db/models/sql/compiler.py", line 974, in execute_sql
    cursor.execute(sql, params)
  File "/home/f/myproject/venv/lib/python3.5/site-packages/django/db/backends/utils.py", line 79, in execute
    return super(CursorDebugWrapper, self).execute(sql, params)
  File "/home/f/myproject/venv/lib/python3.5/site-packages/django/db/backends/utils.py", line 64, in execute
    return self.cursor.execute(sql, params)
  File "/home/f/myproject/venv/lib/python3.5/site-packages/django/db/utils.py", line 97, in __exit__
    six.reraise(dj_exc_type, dj_exc_value, traceback)
  File "/home/f/myproject/venv/lib/python3.5/site-packages/django/utils/six.py", line 658, in reraise
    raise value.with_traceback(tb)
  File "/home/f/myproject/venv/lib/python3.5/site-packages/django/db/backends/utils.py", line 64, in execute
    return self.cursor.execute(sql, params)
  File "/home/f/myproject/venv/lib/python3.5/site-packages/django/db/backends/mysql/base.py", line 124, in execute
    return self.cursor.execute(query, args)
  File "/home/f/myproject/venv/lib/python3.5/site-packages/pymysql/cursors.py", line 166, in execute
    result = self._query(query)
  File "/home/f/myproject/venv/lib/python3.5/site-packages/pymysql/cursors.py", line 322, in _query
    conn.query(q)
  File "/home/f/myproject/venv/lib/python3.5/site-packages/pymysql/connections.py", line 856, in query
    self._affected_rows = self._read_query_result(unbuffered=unbuffered)
  File "/home/f/myproject/venv/lib/python3.5/site-packages/pymysql/connections.py", line 1057, in _read_query_result
    result.read()
  File "/home/f/myproject/venv/lib/python3.5/site-packages/pymysql/connections.py", line 1340, in read
    first_packet = self.connection._read_packet()
  File "/home/f/myproject/venv/lib/python3.5/site-packages/pymysql/connections.py", line 1014, in _read_packet
    packet.check_error()
  File "/home/f/myproject/venv/lib/python3.5/site-packages/pymysql/connections.py", line 393, in check_error
    err.raise_mysql_exception(self._data)
  File "/home/f/myproject/venv/lib/python3.5/site-packages/pymysql/err.py", line 107, in raise_mysql_exception
    raise errorclass(errno, errval)
django.db.utils.IntegrityError: (1048, "Column 'title' cannot be null")
ERROR Internal Server Error: /books/article/4/
Traceback (most recent call last):
  File "/home/f/myproject/venv/lib/python3.5/site-packages/django/db/backends/utils.py", line 64, in execute
    return self.cursor.execute(sql, params)
  File "/home/f/myproject/venv/lib/python3.5/site-packages/django/db/backends/mysql/base.py", line 124, in execute
    return self.cursor.execute(query, args)
  File "/home/f/myproject/venv/lib/python3.5/site-packages/pymysql/cursors.py", line 166, in execute
    result = self._query(query)
  File "/home/f/myproject/venv/lib/python3.5/site-packages/pymysql/cursors.py", line 322, in _query
    conn.query(q)
  File "/home/f/myproject/venv/lib/python3.5/site-packages/pymysql/connections.py", line 856, in query
    self._affected_rows = self._read_query_result(unbuffered=unbuffered)
  File "/home/f/myproject/venv/lib/python3.5/site-packages/pymysql/connections.py", line 1057, in _read_query_result
    result.read()
  File "/home/f/myproject/venv/lib/python3.5/site-packages/pymysql/connections.py", line 1340, in read
    first_packet = self.connection._read_packet()
  File "/home/f/myproject/venv/lib/python3.5/site-packages/pymysql/connections.py", line 1014, in _read_packet
    packet.check_error()
  File "/home/f/myproject/venv/lib/python3.5/site-packages/pymysql/connections.py", line 393, in check_error
    err.raise_mysql_exception(self._data)
  File "/home/f/myproject/venv/lib/python3.5/site-packages/pymysql/err.py", line 107, in raise_mysql_exception
    raise errorclass(errno, errval)
pymysql.err.IntegrityError: (1048, "Column 'title' cannot be null")

The above exception was the direct cause of the following exception:

Traceback (most recent call last):
  File "/home/f/myproject/venv/lib/python3.5/site-packages/django/core/handlers/base.py", line 132, in get_response
    response = wrapped_callback(request, *callback_args, **callback_kwargs)
  File "/home/f/myproject/mybookstore/books/views.py", line 147, in article
    comment.save()
  File "/home/f/myproject/venv/lib/python3.5/site-packages/django/db/models/base.py", line 710, in save
    force_update=force_update, update_fields=update_fields)
  File "/home/f/myproject/venv/lib/python3.5/site-packages/django/db/models/base.py", line 738, in save_base
    updated = self._save_table(raw, cls, force_insert, force_update, using, update_fields)
  File "/home/f/myproject/venv/lib/python3.5/site-packages/django/db/models/base.py", line 822, in _save_table
    result = self._do_insert(cls._base_manager, using, fields, update_pk, raw)
  File "/home/f/myproject/venv/lib/python3.5/site-packages/django/db/models/base.py", line 861, in _do_insert
    using=using, raw=raw)
  File "/home/f/myproject/venv/lib/python3.5/site-packages/django/db/models/manager.py", line 127, in manager_method
    return getattr(self.get_queryset(), name)(*args, **kwargs)
  File "/home/f/myproject/venv/lib/python3.5/site-packages/django/db/models/query.py", line 920, in _insert
    return query.get_compiler(using=using).execute_sql(return_id)
  File "/home/f/myproject/venv/lib/python3.5/site-packages/django/db/models/sql/compiler.py", line 974, in execute_sql
    cursor.execute(sql, params)
  File "/home/f/myproject/venv/lib/python3.5/site-packages/django/db/backends/utils.py", line 79, in execute
    return super(CursorDebugWrapper, self).execute(sql, params)
  File "/home/f/myproject/venv/lib/python3.5/site-packages/django/db/backends/utils.py", line 64, in execute
    return self.cursor.execute(sql, params)
  File "/home/f/myproject/venv/lib/python3.5/site-packages/django/db/utils.py", line 97, in __exit__
    six.reraise(dj_exc_type, dj_exc_value, traceback)
  File "/home/f/myproject/venv/lib/python3.5/site-packages/django/utils/six.py", line 658, in reraise
    raise value.with_traceback(tb)
  File "/home/f/myproject/venv/lib/python3.5/site-packages/django/db/backends/utils.py", line 64, in execute
    return self.cursor.execute(sql, params)
  File "/home/f/myproject/venv/lib/python3.5/site-packages/django/db/backends/mysql/base.py", line 124, in execute
    return self.cursor.execute(query, args)
  File "/home/f/myproject/venv/lib/python3.5/site-packages/pymysql/cursors.py", line 166, in execute
    result = self._query(query)
  File "/home/f/myproject/venv/lib/python3.5/site-packages/pymysql/cursors.py", line 322, in _query
    conn.query(q)
  File "/home/f/myproject/venv/lib/python3.5/site-packages/pymysql/connections.py", line 856, in query
    self._affected_rows = self._read_query_result(unbuffered=unbuffered)
  File "/home/f/myproject/venv/lib/python3.5/site-packages/pymysql/connections.py", line 1057, in _read_query_result
    result.read()
  File "/home/f/myproject/venv/lib/python3.5/site-packages/pymysql/connections.py", line 1340, in read
    first_packet = self.connection._read_packet()
  File "/home/f/myproject/venv/lib/python3.5/site-packages/pymysql/connections.py", line 1014, in _read_packet
    packet.check_error()
  File "/home/f/myproject/venv/lib/python3.5/site-packages/pymysql/connections.py", line 393, in check_error
    err.raise_mysql_exception(self._data)
  File "/home/f/myproject/venv/lib/python3.5/site-packages/pymysql/err.py", line 107, in raise_mysql_exception
    raise errorclass(errno, errval)
django.db.utils.IntegrityError: (1048, "Column 'title' cannot be null")
INFO <django.contrib.sessions.backends.cache.SessionStore object at 0x7fba6d503dd8>
INFO <django.contrib.sessions.backends.cache.SessionStore object at 0x7fba6d503dd8>
WARNING Not Found: /comment/comment/undefined
WARNING Not Found: /comment/comment/undefined
ERROR Internal Server Error: /books/article/19/
Traceback (most recent call last):
  File "/home/f/myproject/venv/lib/python3.5/site-packages/django/db/backends/utils.py", line 64, in execute
    return self.cursor.execute(sql, params)
  File "/home/f/myproject/venv/lib/python3.5/site-packages/django/db/backends/mysql/base.py", line 124, in execute
    return self.cursor.execute(query, args)
  File "/home/f/myproject/venv/lib/python3.5/site-packages/pymysql/cursors.py", line 166, in execute
    result = self._query(query)
  File "/home/f/myproject/venv/lib/python3.5/site-packages/pymysql/cursors.py", line 322, in _query
    conn.query(q)
  File "/home/f/myproject/venv/lib/python3.5/site-packages/pymysql/connections.py", line 856, in query
    self._affected_rows = self._read_query_result(unbuffered=unbuffered)
  File "/home/f/myproject/venv/lib/python3.5/site-packages/pymysql/connections.py", line 1057, in _read_query_result
    result.read()
  File "/home/f/myproject/venv/lib/python3.5/site-packages/pymysql/connections.py", line 1340, in read
    first_packet = self.connection._read_packet()
  File "/home/f/myproject/venv/lib/python3.5/site-packages/pymysql/connections.py", line 1014, in _read_packet
    packet.check_error()
  File "/home/f/myproject/venv/lib/python3.5/site-packages/pymysql/connections.py", line 393, in check_error
    err.raise_mysql_exception(self._data)
  File "/home/f/myproject/venv/lib/python3.5/site-packages/pymysql/err.py", line 107, in raise_mysql_exception
    raise errorclass(errno, errval)
pymysql.err.DataError: (1406, "Data too long for column 'title' at row 1")

The above exception was the direct cause of the following exception:

Traceback (most recent call last):
  File "/home/f/myproject/venv/lib/python3.5/site-packages/django/core/handlers/base.py", line 132, in get_response
    response = wrapped_callback(request, *callback_args, **callback_kwargs)
  File "/home/f/myproject/mybookstore/books/views.py", line 147, in article
    comment.save()
  File "/home/f/myproject/venv/lib/python3.5/site-packages/django/db/models/base.py", line 710, in save
    force_update=force_update, update_fields=update_fields)
  File "/home/f/myproject/venv/lib/python3.5/site-packages/django/db/models/base.py", line 738, in save_base
    updated = self._save_table(raw, cls, force_insert, force_update, using, update_fields)
  File "/home/f/myproject/venv/lib/python3.5/site-packages/django/db/models/base.py", line 822, in _save_table
    result = self._do_insert(cls._base_manager, using, fields, update_pk, raw)
  File "/home/f/myproject/venv/lib/python3.5/site-packages/django/db/models/base.py", line 861, in _do_insert
    using=using, raw=raw)
  File "/home/f/myproject/venv/lib/python3.5/site-packages/django/db/models/manager.py", line 127, in manager_method
    return getattr(self.get_queryset(), name)(*args, **kwargs)
  File "/home/f/myproject/venv/lib/python3.5/site-packages/django/db/models/query.py", line 920, in _insert
    return query.get_compiler(using=using).execute_sql(return_id)
  File "/home/f/myproject/venv/lib/python3.5/site-packages/django/db/models/sql/compiler.py", line 974, in execute_sql
    cursor.execute(sql, params)
  File "/home/f/myproject/venv/lib/python3.5/site-packages/django/db/backends/utils.py", line 79, in execute
    return super(CursorDebugWrapper, self).execute(sql, params)
  File "/home/f/myproject/venv/lib/python3.5/site-packages/django/db/backends/utils.py", line 64, in execute
    return self.cursor.execute(sql, params)
  File "/home/f/myproject/venv/lib/python3.5/site-packages/django/db/utils.py", line 97, in __exit__
    six.reraise(dj_exc_type, dj_exc_value, traceback)
  File "/home/f/myproject/venv/lib/python3.5/site-packages/django/utils/six.py", line 658, in reraise
    raise value.with_traceback(tb)
  File "/home/f/myproject/venv/lib/python3.5/site-packages/django/db/backends/utils.py", line 64, in execute
    return self.cursor.execute(sql, params)
  File "/home/f/myproject/venv/lib/python3.5/site-packages/django/db/backends/mysql/base.py", line 124, in execute
    return self.cursor.execute(query, args)
  File "/home/f/myproject/venv/lib/python3.5/site-packages/pymysql/cursors.py", line 166, in execute
    result = self._query(query)
  File "/home/f/myproject/venv/lib/python3.5/site-packages/pymysql/cursors.py", line 322, in _query
    conn.query(q)
  File "/home/f/myproject/venv/lib/python3.5/site-packages/pymysql/connections.py", line 856, in query
    self._affected_rows = self._read_query_result(unbuffered=unbuffered)
  File "/home/f/myproject/venv/lib/python3.5/site-packages/pymysql/connections.py", line 1057, in _read_query_result
    result.read()
  File "/home/f/myproject/venv/lib/python3.5/site-packages/pymysql/connections.py", line 1340, in read
    first_packet = self.connection._read_packet()
  File "/home/f/myproject/venv/lib/python3.5/site-packages/pymysql/connections.py", line 1014, in _read_packet
    packet.check_error()
  File "/home/f/myproject/venv/lib/python3.5/site-packages/pymysql/connections.py", line 393, in check_error
    err.raise_mysql_exception(self._data)
  File "/home/f/myproject/venv/lib/python3.5/site-packages/pymysql/err.py", line 107, in raise_mysql_exception
    raise errorclass(errno, errval)
django.db.utils.DataError: (1406, "Data too long for column 'title' at row 1")
ERROR Internal Server Error: /books/article/19/
Traceback (most recent call last):
  File "/home/f/myproject/venv/lib/python3.5/site-packages/django/db/backends/utils.py", line 64, in execute
    return self.cursor.execute(sql, params)
  File "/home/f/myproject/venv/lib/python3.5/site-packages/django/db/backends/mysql/base.py", line 124, in execute
    return self.cursor.execute(query, args)
  File "/home/f/myproject/venv/lib/python3.5/site-packages/pymysql/cursors.py", line 166, in execute
    result = self._query(query)
  File "/home/f/myproject/venv/lib/python3.5/site-packages/pymysql/cursors.py", line 322, in _query
    conn.query(q)
  File "/home/f/myproject/venv/lib/python3.5/site-packages/pymysql/connections.py", line 856, in query
    self._affected_rows = self._read_query_result(unbuffered=unbuffered)
  File "/home/f/myproject/venv/lib/python3.5/site-packages/pymysql/connections.py", line 1057, in _read_query_result
    result.read()
  File "/home/f/myproject/venv/lib/python3.5/site-packages/pymysql/connections.py", line 1340, in read
    first_packet = self.connection._read_packet()
  File "/home/f/myproject/venv/lib/python3.5/site-packages/pymysql/connections.py", line 1014, in _read_packet
    packet.check_error()
  File "/home/f/myproject/venv/lib/python3.5/site-packages/pymysql/connections.py", line 393, in check_error
    err.raise_mysql_exception(self._data)
  File "/home/f/myproject/venv/lib/python3.5/site-packages/pymysql/err.py", line 107, in raise_mysql_exception
    raise errorclass(errno, errval)
pymysql.err.DataError: (1406, "Data too long for column 'title' at row 1")

The above exception was the direct cause of the following exception:

Traceback (most recent call last):
  File "/home/f/myproject/venv/lib/python3.5/site-packages/django/core/handlers/base.py", line 132, in get_response
    response = wrapped_callback(request, *callback_args, **callback_kwargs)
  File "/home/f/myproject/mybookstore/books/views.py", line 147, in article
    comment.save()
  File "/home/f/myproject/venv/lib/python3.5/site-packages/django/db/models/base.py", line 710, in save
    force_update=force_update, update_fields=update_fields)
  File "/home/f/myproject/venv/lib/python3.5/site-packages/django/db/models/base.py", line 738, in save_base
    updated = self._save_table(raw, cls, force_insert, force_update, using, update_fields)
  File "/home/f/myproject/venv/lib/python3.5/site-packages/django/db/models/base.py", line 822, in _save_table
    result = self._do_insert(cls._base_manager, using, fields, update_pk, raw)
  File "/home/f/myproject/venv/lib/python3.5/site-packages/django/db/models/base.py", line 861, in _do_insert
    using=using, raw=raw)
  File "/home/f/myproject/venv/lib/python3.5/site-packages/django/db/models/manager.py", line 127, in manager_method
    return getattr(self.get_queryset(), name)(*args, **kwargs)
  File "/home/f/myproject/venv/lib/python3.5/site-packages/django/db/models/query.py", line 920, in _insert
    return query.get_compiler(using=using).execute_sql(return_id)
  File "/home/f/myproject/venv/lib/python3.5/site-packages/django/db/models/sql/compiler.py", line 974, in execute_sql
    cursor.execute(sql, params)
  File "/home/f/myproject/venv/lib/python3.5/site-packages/django/db/backends/utils.py", line 79, in execute
    return super(CursorDebugWrapper, self).execute(sql, params)
  File "/home/f/myproject/venv/lib/python3.5/site-packages/django/db/backends/utils.py", line 64, in execute
    return self.cursor.execute(sql, params)
  File "/home/f/myproject/venv/lib/python3.5/site-packages/django/db/utils.py", line 97, in __exit__
    six.reraise(dj_exc_type, dj_exc_value, traceback)
  File "/home/f/myproject/venv/lib/python3.5/site-packages/django/utils/six.py", line 658, in reraise
    raise value.with_traceback(tb)
  File "/home/f/myproject/venv/lib/python3.5/site-packages/django/db/backends/utils.py", line 64, in execute
    return self.cursor.execute(sql, params)
  File "/home/f/myproject/venv/lib/python3.5/site-packages/django/db/backends/mysql/base.py", line 124, in execute
    return self.cursor.execute(query, args)
  File "/home/f/myproject/venv/lib/python3.5/site-packages/pymysql/cursors.py", line 166, in execute
    result = self._query(query)
  File "/home/f/myproject/venv/lib/python3.5/site-packages/pymysql/cursors.py", line 322, in _query
    conn.query(q)
  File "/home/f/myproject/venv/lib/python3.5/site-packages/pymysql/connections.py", line 856, in query
    self._affected_rows = self._read_query_result(unbuffered=unbuffered)
  File "/home/f/myproject/venv/lib/python3.5/site-packages/pymysql/connections.py", line 1057, in _read_query_result
    result.read()
  File "/home/f/myproject/venv/lib/python3.5/site-packages/pymysql/connections.py", line 1340, in read
    first_packet = self.connection._read_packet()
  File "/home/f/myproject/venv/lib/python3.5/site-packages/pymysql/connections.py", line 1014, in _read_packet
    packet.check_error()
  File "/home/f/myproject/venv/lib/python3.5/site-packages/pymysql/connections.py", line 393, in check_error
    err.raise_mysql_exception(self._data)
  File "/home/f/myproject/venv/lib/python3.5/site-packages/pymysql/err.py", line 107, in raise_mysql_exception
    raise errorclass(errno, errval)
django.db.utils.DataError: (1406, "Data too long for column 'title' at row 1")
WARNING Not Found: /books/article/
WARNING Not Found: /books/article/
INFO <django.contrib.sessions.backends.cache.SessionStore object at 0x7fba6c09ce80>
INFO <django.contrib.sessions.backends.cache.SessionStore object at 0x7fba6c09ce80>
WARNING Not Found: /comment/comment/undefined
WARNING Not Found: /comment/comment/undefined
ERROR Internal Server Error: /books/article/3/
Traceback (most recent call last):
  File "/home/f/myproject/venv/lib/python3.5/site-packages/django/core/handlers/base.py", line 132, in get_response
    response = wrapped_callback(request, *callback_args, **callback_kwargs)
  File "/home/f/myproject/mybookstore/books/views.py", line 153, in article
    return redirect(reverse('books:article', context))
  File "/home/f/myproject/venv/lib/python3.5/site-packages/django/core/urlresolvers.py", line 528, in reverse
    resolver = get_resolver(urlconf)
TypeError: unhashable type: 'dict'
ERROR Internal Server Error: /books/article/3/
Traceback (most recent call last):
  File "/home/f/myproject/venv/lib/python3.5/site-packages/django/core/handlers/base.py", line 132, in get_response
    response = wrapped_callback(request, *callback_args, **callback_kwargs)
  File "/home/f/myproject/mybookstore/books/views.py", line 153, in article
    return redirect(reverse('books:article', context))
  File "/home/f/myproject/venv/lib/python3.5/site-packages/django/core/urlresolvers.py", line 528, in reverse
    resolver = get_resolver(urlconf)
TypeError: unhashable type: 'dict'
INFO <django.contrib.sessions.backends.cache.SessionStore object at 0x7f1f50148dd8>
INFO <django.contrib.sessions.backends.cache.SessionStore object at 0x7f1f50148dd8>
WARNING Not Found: /comment/comment/undefined
WARNING Not Found: /comment/comment/undefined
ERROR Internal Server Error: /books/article/3/
Traceback (most recent call last):
  File "/home/f/myproject/venv/lib/python3.5/site-packages/django/core/handlers/base.py", line 132, in get_response
    response = wrapped_callback(request, *callback_args, **callback_kwargs)
  File "/home/f/myproject/mybookstore/books/views.py", line 153, in article
    return redirect(reverse('books:article'), context)
  File "/home/f/myproject/venv/lib/python3.5/site-packages/django/core/urlresolvers.py", line 579, in reverse
    return force_text(iri_to_uri(resolver._reverse_with_prefix(view, prefix, *args, **kwargs)))
  File "/home/f/myproject/venv/lib/python3.5/site-packages/django/core/urlresolvers.py", line 496, in _reverse_with_prefix
    (lookup_view_s, args, kwargs, len(patterns), patterns))
django.core.urlresolvers.NoReverseMatch: Reverse for 'article' with arguments '()' and keyword arguments '{}' not found. 1 pattern(s) tried: ['books/article/(?P<book_id>\\d+)/$']
ERROR Internal Server Error: /books/article/3/
Traceback (most recent call last):
  File "/home/f/myproject/venv/lib/python3.5/site-packages/django/core/handlers/base.py", line 132, in get_response
    response = wrapped_callback(request, *callback_args, **callback_kwargs)
  File "/home/f/myproject/mybookstore/books/views.py", line 153, in article
    return redirect(reverse('books:article'), context)
  File "/home/f/myproject/venv/lib/python3.5/site-packages/django/core/urlresolvers.py", line 579, in reverse
    return force_text(iri_to_uri(resolver._reverse_with_prefix(view, prefix, *args, **kwargs)))
  File "/home/f/myproject/venv/lib/python3.5/site-packages/django/core/urlresolvers.py", line 496, in _reverse_with_prefix
    (lookup_view_s, args, kwargs, len(patterns), patterns))
django.core.urlresolvers.NoReverseMatch: Reverse for 'article' with arguments '()' and keyword arguments '{}' not found. 1 pattern(s) tried: ['books/article/(?P<book_id>\\d+)/$']
ERROR Internal Server Error: /books/article/3/
Traceback (most recent call last):
  File "/home/f/myproject/venv/lib/python3.5/site-packages/django/core/urlresolvers.py", line 394, in urlconf_module
    return self._urlconf_module
AttributeError: 'RegexURLResolver' object has no attribute '_urlconf_module'

During handling of the above exception, another exception occurred:

Traceback (most recent call last):
  File "/home/f/myproject/venv/lib/python3.5/site-packages/django/core/handlers/base.py", line 132, in get_response
    response = wrapped_callback(request, *callback_args, **callback_kwargs)
  File "/home/f/myproject/mybookstore/books/views.py", line 153, in article
    return redirect(reverse('books:article', book_id, context))
  File "/home/f/myproject/venv/lib/python3.5/site-packages/django/core/urlresolvers.py", line 550, in reverse
    app_list = resolver.app_dict[ns]
  File "/home/f/myproject/venv/lib/python3.5/site-packages/django/core/urlresolvers.py", line 352, in app_dict
    self._populate()
  File "/home/f/myproject/venv/lib/python3.5/site-packages/django/core/urlresolvers.py", line 285, in _populate
    for pattern in reversed(self.url_patterns):
  File "/home/f/myproject/venv/lib/python3.5/site-packages/django/core/urlresolvers.py", line 402, in url_patterns
    patterns = getattr(self.urlconf_module, "urlpatterns", self.urlconf_module)
  File "/home/f/myproject/venv/lib/python3.5/site-packages/django/core/urlresolvers.py", line 396, in urlconf_module
    self._urlconf_module = import_module(self.urlconf_name)
  File "/home/f/myproject/venv/lib/python3.5/importlib/__init__.py", line 126, in import_module
    return _bootstrap._gcd_import(name[level:], package, level)
  File "<frozen importlib._bootstrap>", line 986, in _gcd_import
  File "<frozen importlib._bootstrap>", line 969, in _find_and_load
  File "<frozen importlib._bootstrap>", line 956, in _find_and_load_unlocked
ImportError: No module named '3'
ERROR Internal Server Error: /books/article/3/
Traceback (most recent call last):
  File "/home/f/myproject/venv/lib/python3.5/site-packages/django/core/urlresolvers.py", line 394, in urlconf_module
    return self._urlconf_module
AttributeError: 'RegexURLResolver' object has no attribute '_urlconf_module'

During handling of the above exception, another exception occurred:

Traceback (most recent call last):
  File "/home/f/myproject/venv/lib/python3.5/site-packages/django/core/handlers/base.py", line 132, in get_response
    response = wrapped_callback(request, *callback_args, **callback_kwargs)
  File "/home/f/myproject/mybookstore/books/views.py", line 153, in article
    return redirect(reverse('books:article', book_id, context))
  File "/home/f/myproject/venv/lib/python3.5/site-packages/django/core/urlresolvers.py", line 550, in reverse
    app_list = resolver.app_dict[ns]
  File "/home/f/myproject/venv/lib/python3.5/site-packages/django/core/urlresolvers.py", line 352, in app_dict
    self._populate()
  File "/home/f/myproject/venv/lib/python3.5/site-packages/django/core/urlresolvers.py", line 285, in _populate
    for pattern in reversed(self.url_patterns):
  File "/home/f/myproject/venv/lib/python3.5/site-packages/django/core/urlresolvers.py", line 402, in url_patterns
    patterns = getattr(self.urlconf_module, "urlpatterns", self.urlconf_module)
  File "/home/f/myproject/venv/lib/python3.5/site-packages/django/core/urlresolvers.py", line 396, in urlconf_module
    self._urlconf_module = import_module(self.urlconf_name)
  File "/home/f/myproject/venv/lib/python3.5/importlib/__init__.py", line 126, in import_module
    return _bootstrap._gcd_import(name[level:], package, level)
  File "<frozen importlib._bootstrap>", line 986, in _gcd_import
  File "<frozen importlib._bootstrap>", line 969, in _find_and_load
  File "<frozen importlib._bootstrap>", line 956, in _find_and_load_unlocked
ImportError: No module named '3'
INFO <django.contrib.sessions.backends.cache.SessionStore object at 0x7fbbe814f860>
INFO <django.contrib.sessions.backends.cache.SessionStore object at 0x7fbbe814f860>
INFO <django.contrib.sessions.backends.cache.SessionStore object at 0x7f98f5f9f898>
INFO <django.contrib.sessions.backends.cache.SessionStore object at 0x7f98f5f9f898>
INFO <django.contrib.sessions.backends.cache.SessionStore object at 0x7f98f4027a20>
INFO <django.contrib.sessions.backends.cache.SessionStore object at 0x7f98f4027a20>
INFO <django.contrib.sessions.backends.cache.SessionStore object at 0x7f05340ec8d0>
INFO <django.contrib.sessions.backends.cache.SessionStore object at 0x7f05340ec8d0>
INFO <django.contrib.sessions.backends.cache.SessionStore object at 0x7f5694688080>
INFO <django.contrib.sessions.backends.cache.SessionStore object at 0x7f5694688080>
INFO <django.contrib.sessions.backends.cache.SessionStore object at 0x7f5694b638d0>
INFO <django.contrib.sessions.backends.cache.SessionStore object at 0x7f5694b638d0>
INFO <django.contrib.sessions.backends.cache.SessionStore object at 0x7f5691984358>
INFO <django.contrib.sessions.backends.cache.SessionStore object at 0x7f5691984358>
INFO <django.contrib.sessions.backends.cache.SessionStore object at 0x7f5691c44b70>
INFO <django.contrib.sessions.backends.cache.SessionStore object at 0x7f5691c44b70>
INFO <django.contrib.sessions.backends.cache.SessionStore object at 0x7f5694b47748>
INFO <django.contrib.sessions.backends.cache.SessionStore object at 0x7f5694b47748>
INFO <django.contrib.sessions.backends.cache.SessionStore object at 0x7f5691916c88>
INFO <django.contrib.sessions.backends.cache.SessionStore object at 0x7f5691916c88>
INFO <django.contrib.sessions.backends.cache.SessionStore object at 0x7f5691905eb8>
INFO <django.contrib.sessions.backends.cache.SessionStore object at 0x7f5691905eb8>
INFO <django.contrib.sessions.backends.cache.SessionStore object at 0x7f56916a8da0>
INFO <django.contrib.sessions.backends.cache.SessionStore object at 0x7f56916a8da0>
INFO <django.contrib.sessions.backends.cache.SessionStore object at 0x7f568feb3f28>
INFO <django.contrib.sessions.backends.cache.SessionStore object at 0x7f568feb3f28>
INFO <django.contrib.sessions.backends.cache.SessionStore object at 0x7f5691969208>
INFO <django.contrib.sessions.backends.cache.SessionStore object at 0x7f5691969208>
INFO <django.contrib.sessions.backends.cache.SessionStore object at 0x7f5691905710>
INFO <django.contrib.sessions.backends.cache.SessionStore object at 0x7f5691905710>
INFO <django.contrib.sessions.backends.cache.SessionStore object at 0x7f568fe4ebe0>
INFO <django.contrib.sessions.backends.cache.SessionStore object at 0x7f568fe4ebe0>
INFO <django.contrib.sessions.backends.cache.SessionStore object at 0x7f5691c346d8>
INFO <django.contrib.sessions.backends.cache.SessionStore object at 0x7f5691c346d8>
INFO <django.contrib.sessions.backends.cache.SessionStore object at 0x7f568ff002b0>
INFO <django.contrib.sessions.backends.cache.SessionStore object at 0x7f568ff002b0>
INFO <django.contrib.sessions.backends.cache.SessionStore object at 0x7f568ff02be0>
INFO <django.contrib.sessions.backends.cache.SessionStore object at 0x7f568ff02be0>
INFO <django.contrib.sessions.backends.cache.SessionStore object at 0x7f568fe4e780>
INFO <django.contrib.sessions.backends.cache.SessionStore object at 0x7f568fe4e780>
INFO <django.contrib.sessions.backends.cache.SessionStore object at 0x7f568fe5c4a8>
INFO <django.contrib.sessions.backends.cache.SessionStore object at 0x7f568fe5c4a8>
INFO <django.contrib.sessions.backends.cache.SessionStore object at 0x7f568fe32518>
INFO <django.contrib.sessions.backends.cache.SessionStore object at 0x7f568fe32518>
INFO <django.contrib.sessions.backends.cache.SessionStore object at 0x7f568fd18978>
INFO <django.contrib.sessions.backends.cache.SessionStore object at 0x7f568fd18978>
INFO <django.contrib.sessions.backends.cache.SessionStore object at 0x7f568fe7ca58>
INFO <django.contrib.sessions.backends.cache.SessionStore object at 0x7f568fe7ca58>
INFO <django.contrib.sessions.backends.cache.SessionStore object at 0x7f568fd18a58>
INFO <django.contrib.sessions.backends.cache.SessionStore object at 0x7f568fd18a58>
INFO <django.contrib.sessions.backends.cache.SessionStore object at 0x7f568fe3cac8>
INFO <django.contrib.sessions.backends.cache.SessionStore object at 0x7f568fe3cac8>
WARNING Not Found: /favicon.ico
WARNING Not Found: /favicon.ico
INFO <django.contrib.sessions.backends.cache.SessionStore object at 0x7f568fd21908>
INFO <django.contrib.sessions.backends.cache.SessionStore object at 0x7f568fd21908>
INFO <django.contrib.sessions.backends.cache.SessionStore object at 0x7f568fd18e10>
INFO <django.contrib.sessions.backends.cache.SessionStore object at 0x7f568fd18e10>
INFO <django.contrib.sessions.backends.cache.SessionStore object at 0x7f568fe434a8>
INFO <django.contrib.sessions.backends.cache.SessionStore object at 0x7f568fe434a8>
INFO <django.contrib.sessions.backends.cache.SessionStore object at 0x7f568fe5cba8>
INFO <django.contrib.sessions.backends.cache.SessionStore object at 0x7f568fe5cba8>
INFO <django.contrib.sessions.backends.cache.SessionStore object at 0x7f568fccacf8>
INFO <django.contrib.sessions.backends.cache.SessionStore object at 0x7f568fccacf8>
INFO <django.contrib.sessions.backends.cache.SessionStore object at 0x7f568fe61f28>
INFO <django.contrib.sessions.backends.cache.SessionStore object at 0x7f568fe61f28>
INFO <django.contrib.sessions.backends.cache.SessionStore object at 0x7f5691912c18>
INFO <django.contrib.sessions.backends.cache.SessionStore object at 0x7f5691912c18>
WARNING Not Found: /sdk
WARNING Not Found: /sdk
WARNING Not Found: /nmaplowercheck1528898440
WARNING Not Found: /nmaplowercheck1528898440
INFO <django.contrib.sessions.backends.cache.SessionStore object at 0x7f568fd85b00>
INFO <django.contrib.sessions.backends.cache.SessionStore object at 0x7f568fd85b00>
WARNING Not Found: /HNAP1
WARNING Not Found: /HNAP1
INFO <django.contrib.sessions.backends.cache.SessionStore object at 0x7f568fe89320>
INFO <django.contrib.sessions.backends.cache.SessionStore object at 0x7f568fe89320>
WARNING Not Found: /ifixwebspace/
WARNING Not Found: /ifixwebspace/
WARNING Not Found: /navigation.html
WARNING Not Found: /navigation.html
INFO <django.contrib.sessions.backends.cache.SessionStore object at 0x7f568fd3a908>
INFO <django.contrib.sessions.backends.cache.SessionStore object at 0x7f568fd3a908>
WARNING Not Found: /web_caps/webCapsConfig
WARNING Not Found: /web_caps/webCapsConfig
WARNING Not Found: /image/lgbg.jpg
WARNING Not Found: /image/lgbg.jpg
INFO <django.contrib.sessions.backends.cache.SessionStore object at 0x7f568fd30128>
INFO <django.contrib.sessions.backends.cache.SessionStore object at 0x7f568fd30128>
INFO <django.contrib.sessions.backends.cache.SessionStore object at 0x7f56918cd5f8>
INFO <django.contrib.sessions.backends.cache.SessionStore object at 0x7f56918cd5f8>
INFO <django.contrib.sessions.backends.cache.SessionStore object at 0x7f568fd13978>
INFO <django.contrib.sessions.backends.cache.SessionStore object at 0x7f568fd13978>
INFO <django.contrib.sessions.backends.cache.SessionStore object at 0x7f568fe5a828>
INFO <django.contrib.sessions.backends.cache.SessionStore object at 0x7f568fe5a828>
INFO <django.contrib.sessions.backends.cache.SessionStore object at 0x7f568febc080>
INFO <django.contrib.sessions.backends.cache.SessionStore object at 0x7f568febc080>
INFO <django.contrib.sessions.backends.cache.SessionStore object at 0x7f568fe50438>
INFO <django.contrib.sessions.backends.cache.SessionStore object at 0x7f568fe50438>
INFO <django.contrib.sessions.backends.cache.SessionStore object at 0x7f568fd3d1d0>
INFO <django.contrib.sessions.backends.cache.SessionStore object at 0x7f568fd3d1d0>
INFO <django.contrib.sessions.backends.cache.SessionStore object at 0x7f56919536d8>
INFO <django.contrib.sessions.backends.cache.SessionStore object at 0x7f56919536d8>
INFO <django.contrib.sessions.backends.cache.SessionStore object at 0x7f568feb8470>
INFO <django.contrib.sessions.backends.cache.SessionStore object at 0x7f568feb8470>
WARNING Not Found: /phpmyadmin/scripts/setup.php
WARNING Not Found: /phpmyadmin/scripts/setup.php
INFO <django.contrib.sessions.backends.cache.SessionStore object at 0x7f568fe89ba8>
INFO <django.contrib.sessions.backends.cache.SessionStore object at 0x7f568fe89ba8>
INFO <django.contrib.sessions.backends.cache.SessionStore object at 0x7f568fe32128>
INFO <django.contrib.sessions.backends.cache.SessionStore object at 0x7f568fe32128>
INFO <django.contrib.sessions.backends.cache.SessionStore object at 0x7f568fcccbe0>
INFO <django.contrib.sessions.backends.cache.SessionStore object at 0x7f568fcccbe0>
INFO <django.contrib.sessions.backends.cache.SessionStore object at 0x7f568fcd49e8>
INFO <django.contrib.sessions.backends.cache.SessionStore object at 0x7f568fcd49e8>
INFO <django.contrib.sessions.backends.cache.SessionStore object at 0x7f568fe38b38>
INFO <django.contrib.sessions.backends.cache.SessionStore object at 0x7f568fe38b38>
INFO <django.contrib.sessions.backends.cache.SessionStore object at 0x7f568fe2dbe0>
INFO <django.contrib.sessions.backends.cache.SessionStore object at 0x7f568fe2dbe0>
INFO <django.contrib.sessions.backends.cache.SessionStore object at 0x7f568fd18470>
INFO <django.contrib.sessions.backends.cache.SessionStore object at 0x7f568fd18470>
INFO <django.contrib.sessions.backends.cache.SessionStore object at 0x7f568fe24a20>
INFO <django.contrib.sessions.backends.cache.SessionStore object at 0x7f568fe24a20>
INFO <django.contrib.sessions.backends.cache.SessionStore object at 0x7f568fe89b70>
INFO <django.contrib.sessions.backends.cache.SessionStore object at 0x7f568fe89b70>
INFO <django.contrib.sessions.backends.cache.SessionStore object at 0x7f568fd18f98>
INFO <django.contrib.sessions.backends.cache.SessionStore object at 0x7f568fd18f98>
INFO <django.contrib.sessions.backends.cache.SessionStore object at 0x7f5691946e48>
INFO <django.contrib.sessions.backends.cache.SessionStore object at 0x7f5691946e48>
INFO <django.contrib.sessions.backends.cache.SessionStore object at 0x7f568feeafd0>
INFO <django.contrib.sessions.backends.cache.SessionStore object at 0x7f568feeafd0>
INFO <django.contrib.sessions.backends.cache.SessionStore object at 0x7f568fe25a20>
INFO <django.contrib.sessions.backends.cache.SessionStore object at 0x7f568fe25a20>
INFO <django.contrib.sessions.backends.cache.SessionStore object at 0x7f569193ae80>
INFO <django.contrib.sessions.backends.cache.SessionStore object at 0x7f569193ae80>
INFO <django.contrib.sessions.backends.cache.SessionStore object at 0x7f568fe61ba8>
INFO <django.contrib.sessions.backends.cache.SessionStore object at 0x7f568fe61ba8>
INFO <django.contrib.sessions.backends.cache.SessionStore object at 0x7f568fe24240>
INFO <django.contrib.sessions.backends.cache.SessionStore object at 0x7f568fe24240>
INFO <django.contrib.sessions.backends.cache.SessionStore object at 0x7f568ff1eb00>
INFO <django.contrib.sessions.backends.cache.SessionStore object at 0x7f568ff1eb00>
INFO <django.contrib.sessions.backends.cache.SessionStore object at 0x7f568fef0198>
INFO <django.contrib.sessions.backends.cache.SessionStore object at 0x7f568fef0198>
INFO <django.contrib.sessions.backends.cache.SessionStore object at 0x7f568fd3a470>
INFO <django.contrib.sessions.backends.cache.SessionStore object at 0x7f568fd3a470>
INFO <django.contrib.sessions.backends.cache.SessionStore object at 0x7f568fefb3c8>
INFO <django.contrib.sessions.backends.cache.SessionStore object at 0x7f568fefb3c8>
INFO <django.contrib.sessions.backends.cache.SessionStore object at 0x7f568fe74f98>
INFO <django.contrib.sessions.backends.cache.SessionStore object at 0x7f568fe74f98>
INFO <django.contrib.sessions.backends.cache.SessionStore object at 0x7f568feb8278>
INFO <django.contrib.sessions.backends.cache.SessionStore object at 0x7f568feb8278>
INFO <django.contrib.sessions.backends.cache.SessionStore object at 0x7f568fe7cc88>
INFO <django.contrib.sessions.backends.cache.SessionStore object at 0x7f568fe7cc88>
INFO <django.contrib.sessions.backends.cache.SessionStore object at 0x7f5694b47898>
INFO <django.contrib.sessions.backends.cache.SessionStore object at 0x7f5694b47898>
INFO <django.contrib.sessions.backends.cache.SessionStore object at 0x7f568fd63710>
INFO <django.contrib.sessions.backends.cache.SessionStore object at 0x7f568fd63710>
INFO <django.contrib.sessions.backends.cache.SessionStore object at 0x7f5694b920f0>
INFO <django.contrib.sessions.backends.cache.SessionStore object at 0x7f5694b920f0>
INFO <django.contrib.sessions.backends.cache.SessionStore object at 0x7f56946485f8>
INFO <django.contrib.sessions.backends.cache.SessionStore object at 0x7f56946485f8>
WARNING Not Found: /cache/global/img/gs.gif
WARNING Not Found: /cache/global/img/gs.gif
INFO <django.contrib.sessions.backends.cache.SessionStore object at 0x7f568fe44f98>
INFO <django.contrib.sessions.backends.cache.SessionStore object at 0x7f568fe44f98>
INFO <django.contrib.sessions.backends.cache.SessionStore object at 0x7f568fd36f60>
INFO <django.contrib.sessions.backends.cache.SessionStore object at 0x7f568fd36f60>
INFO <django.contrib.sessions.backends.cache.SessionStore object at 0x7f568fd39f28>
INFO <django.contrib.sessions.backends.cache.SessionStore object at 0x7f568fd39f28>
INFO <django.contrib.sessions.backends.cache.SessionStore object at 0x7f568fef6e48>
INFO <django.contrib.sessions.backends.cache.SessionStore object at 0x7f568fef6e48>
INFO <django.contrib.sessions.backends.cache.SessionStore object at 0x7f569168a470>
INFO <django.contrib.sessions.backends.cache.SessionStore object at 0x7f569168a470>
INFO <django.contrib.sessions.backends.cache.SessionStore object at 0x7f568fe77ef0>
INFO <django.contrib.sessions.backends.cache.SessionStore object at 0x7f568fe77ef0>
INFO <django.contrib.sessions.backends.cache.SessionStore object at 0x7f56946bc630>
INFO <django.contrib.sessions.backends.cache.SessionStore object at 0x7f56946bc630>
INFO <django.contrib.sessions.backends.cache.SessionStore object at 0x7f568fcca978>
INFO <django.contrib.sessions.backends.cache.SessionStore object at 0x7f568fcca978>
INFO <django.contrib.sessions.backends.cache.SessionStore object at 0x7f5691912b38>
INFO <django.contrib.sessions.backends.cache.SessionStore object at 0x7f5691912b38>
INFO <django.contrib.sessions.backends.cache.SessionStore object at 0x7f568fef0f98>
INFO <django.contrib.sessions.backends.cache.SessionStore object at 0x7f568fef0f98>
INFO <django.contrib.sessions.backends.cache.SessionStore object at 0x7f568feea978>
INFO <django.contrib.sessions.backends.cache.SessionStore object at 0x7f568feea978>
INFO <django.contrib.sessions.backends.cache.SessionStore object at 0x7f568fe43080>
INFO <django.contrib.sessions.backends.cache.SessionStore object at 0x7f568fe43080>
INFO <django.contrib.sessions.backends.cache.SessionStore object at 0x7f568fe38e80>
INFO <django.contrib.sessions.backends.cache.SessionStore object at 0x7f568fe38e80>
INFO <django.contrib.sessions.backends.cache.SessionStore object at 0x7f568fe65e48>
INFO <django.contrib.sessions.backends.cache.SessionStore object at 0x7f568fe65e48>
INFO <django.contrib.sessions.backends.cache.SessionStore object at 0x7f569195b2e8>
INFO <django.contrib.sessions.backends.cache.SessionStore object at 0x7f569195b2e8>
INFO <django.contrib.sessions.backends.cache.SessionStore object at 0x7f568fe7a908>
INFO <django.contrib.sessions.backends.cache.SessionStore object at 0x7f568fe7a908>
INFO <django.contrib.sessions.backends.cache.SessionStore object at 0x7f568fd52828>
INFO <django.contrib.sessions.backends.cache.SessionStore object at 0x7f568fd52828>
INFO <django.contrib.sessions.backends.cache.SessionStore object at 0x7f568fe6c240>
INFO <django.contrib.sessions.backends.cache.SessionStore object at 0x7f568fe6c240>
INFO <django.contrib.sessions.backends.cache.SessionStore object at 0x7f568fe80b00>
INFO <django.contrib.sessions.backends.cache.SessionStore object at 0x7f568fe80b00>
INFO <django.contrib.sessions.backends.cache.SessionStore object at 0x7f569164f390>
INFO <django.contrib.sessions.backends.cache.SessionStore object at 0x7f569164f390>
INFO <django.contrib.sessions.backends.cache.SessionStore object at 0x7f568fecaf28>
INFO <django.contrib.sessions.backends.cache.SessionStore object at 0x7f568fecaf28>
INFO <django.contrib.sessions.backends.cache.SessionStore object at 0x7f56918fb588>
INFO <django.contrib.sessions.backends.cache.SessionStore object at 0x7f56918fb588>
INFO <django.contrib.sessions.backends.cache.SessionStore object at 0x7f568fd1f780>
INFO <django.contrib.sessions.backends.cache.SessionStore object at 0x7f568fd1f780>
INFO <django.contrib.sessions.backends.cache.SessionStore object at 0x7f5691956198>
INFO <django.contrib.sessions.backends.cache.SessionStore object at 0x7f5691956198>
WARNING Not Found: /cache/global/img/gs.gif
WARNING Not Found: /cache/global/img/gs.gif
INFO <django.contrib.sessions.backends.cache.SessionStore object at 0x7f568fe50c18>
INFO <django.contrib.sessions.backends.cache.SessionStore object at 0x7f568fe50c18>
INFO <django.contrib.sessions.backends.cache.SessionStore object at 0x7f5691672d68>
INFO <django.contrib.sessions.backends.cache.SessionStore object at 0x7f5691672d68>
INFO <django.contrib.sessions.backends.cache.SessionStore object at 0x7f5691694fd0>
INFO <django.contrib.sessions.backends.cache.SessionStore object at 0x7f5691694fd0>
INFO <django.contrib.sessions.backends.cache.SessionStore object at 0x7f568fe66240>
INFO <django.contrib.sessions.backends.cache.SessionStore object at 0x7f568fe66240>
INFO <django.contrib.sessions.backends.cache.SessionStore object at 0x7f568fe5a828>
INFO <django.contrib.sessions.backends.cache.SessionStore object at 0x7f568fe5a828>
INFO <django.contrib.sessions.backends.cache.SessionStore object at 0x7f568fd85128>
INFO <django.contrib.sessions.backends.cache.SessionStore object at 0x7f568fd85128>
INFO <django.contrib.sessions.backends.cache.SessionStore object at 0x7f568ff095c0>
INFO <django.contrib.sessions.backends.cache.SessionStore object at 0x7f568ff095c0>
INFO <django.contrib.sessions.backends.cache.SessionStore object at 0x7f568fef0198>
INFO <django.contrib.sessions.backends.cache.SessionStore object at 0x7f568fef0198>
INFO <django.contrib.sessions.backends.cache.SessionStore object at 0x7f568feb8710>
INFO <django.contrib.sessions.backends.cache.SessionStore object at 0x7f568feb8710>
INFO <django.contrib.sessions.backends.cache.SessionStore object at 0x7f5691c1a748>
INFO <django.contrib.sessions.backends.cache.SessionStore object at 0x7f5691c1a748>
INFO <django.contrib.sessions.backends.cache.SessionStore object at 0x7f568fd6bc50>
INFO <django.contrib.sessions.backends.cache.SessionStore object at 0x7f568fd6bc50>
INFO <django.contrib.sessions.backends.cache.SessionStore object at 0x7f568fd134e0>
INFO <django.contrib.sessions.backends.cache.SessionStore object at 0x7f568fd134e0>
INFO <django.contrib.sessions.backends.cache.SessionStore object at 0x7f568fef1358>
INFO <django.contrib.sessions.backends.cache.SessionStore object at 0x7f568fef1358>
INFO <django.contrib.sessions.backends.cache.SessionStore object at 0x7f56916a8e48>
INFO <django.contrib.sessions.backends.cache.SessionStore object at 0x7f56916a8e48>
INFO <django.contrib.sessions.backends.cache.SessionStore object at 0x7f568fd7d2b0>
INFO <django.contrib.sessions.backends.cache.SessionStore object at 0x7f568fd7d2b0>
INFO <django.contrib.sessions.backends.cache.SessionStore object at 0x7f568fe4e588>
INFO <django.contrib.sessions.backends.cache.SessionStore object at 0x7f568fe4e588>
INFO <django.contrib.sessions.backends.cache.SessionStore object at 0x7f568fe80be0>
INFO <django.contrib.sessions.backends.cache.SessionStore object at 0x7f568fe80be0>
INFO <django.contrib.sessions.backends.cache.SessionStore object at 0x7f568fe5c0f0>
INFO <django.contrib.sessions.backends.cache.SessionStore object at 0x7f568fe5c0f0>
INFO <django.contrib.sessions.backends.cache.SessionStore object at 0x7f5691916208>
INFO <django.contrib.sessions.backends.cache.SessionStore object at 0x7f5691916208>
INFO <django.contrib.sessions.backends.cache.SessionStore object at 0x7f568ff1ac18>
INFO <django.contrib.sessions.backends.cache.SessionStore object at 0x7f568ff1ac18>
INFO <django.contrib.sessions.backends.cache.SessionStore object at 0x7f568feb5cc0>
INFO <django.contrib.sessions.backends.cache.SessionStore object at 0x7f568feb5cc0>
INFO <django.contrib.sessions.backends.cache.SessionStore object at 0x7f568fcd4278>
INFO <django.contrib.sessions.backends.cache.SessionStore object at 0x7f568fcd4278>
INFO <django.contrib.sessions.backends.cache.SessionStore object at 0x7f568fe74550>
INFO <django.contrib.sessions.backends.cache.SessionStore object at 0x7f568fe74550>
INFO <django.contrib.sessions.backends.cache.SessionStore object at 0x7f568fef1f60>
INFO <django.contrib.sessions.backends.cache.SessionStore object at 0x7f568fef1f60>
WARNING Not Found: /favicon.ico
WARNING Not Found: /favicon.ico
INFO <django.contrib.sessions.backends.cache.SessionStore object at 0x7f568fd0ee48>
INFO <django.contrib.sessions.backends.cache.SessionStore object at 0x7f568fd0ee48>
INFO <django.contrib.sessions.backends.cache.SessionStore object at 0x7f56918cd5f8>
INFO <django.contrib.sessions.backends.cache.SessionStore object at 0x7f56918cd5f8>
INFO <django.contrib.sessions.backends.cache.SessionStore object at 0x7f568fd18400>
INFO <django.contrib.sessions.backends.cache.SessionStore object at 0x7f568fd18400>
INFO <django.contrib.sessions.backends.cache.SessionStore object at 0x7f568fcd7048>
INFO <django.contrib.sessions.backends.cache.SessionStore object at 0x7f568fcd7048>
INFO <django.contrib.sessions.backends.cache.SessionStore object at 0x7f569193af28>
INFO <django.contrib.sessions.backends.cache.SessionStore object at 0x7f569193af28>
INFO <django.contrib.sessions.backends.cache.SessionStore object at 0x7f568bb23710>
INFO <django.contrib.sessions.backends.cache.SessionStore object at 0x7f568bb23710>
INFO <django.contrib.sessions.backends.cache.SessionStore object at 0x7f568fd03a58>
INFO <django.contrib.sessions.backends.cache.SessionStore object at 0x7f568fd03a58>
INFO <django.contrib.sessions.backends.cache.SessionStore object at 0x7f568fe43358>
INFO <django.contrib.sessions.backends.cache.SessionStore object at 0x7f568fe43358>
INFO <django.contrib.sessions.backends.cache.SessionStore object at 0x7f568b4f7710>
INFO <django.contrib.sessions.backends.cache.SessionStore object at 0x7f568b4f7710>
INFO <django.contrib.sessions.backends.cache.SessionStore object at 0x7f568dbab048>
INFO <django.contrib.sessions.backends.cache.SessionStore object at 0x7f568dbab048>
INFO <django.contrib.sessions.backends.cache.SessionStore object at 0x7f568b4db6d8>
INFO <django.contrib.sessions.backends.cache.SessionStore object at 0x7f568b4db6d8>
WARNING Not Found: /comment/comment/undefined
WARNING Not Found: /comment/comment/undefined
WARNING Not Found: /comment/comment/undefined
WARNING Not Found: /comment/comment/undefined
WARNING Not Found: /comment/comment/undefined
WARNING Not Found: /comment/comment/undefined
INFO <django.contrib.sessions.backends.cache.SessionStore object at 0x7f568fcd72b0>
INFO <django.contrib.sessions.backends.cache.SessionStore object at 0x7f568fcd72b0>
WARNING Not Found: /comment/comment/undefined
WARNING Not Found: /comment/comment/undefined
INFO <django.contrib.sessions.backends.cache.SessionStore object at 0x7f568b3e8b00>
INFO <django.contrib.sessions.backends.cache.SessionStore object at 0x7f568b3e8b00>
WARNING Not Found: /comment/comment/undefined
WARNING Not Found: /comment/comment/undefined
ERROR Internal Server Error: /user/address/
Traceback (most recent call last):
  File "/root/zuoyuan/python3/lib/python3.5/site-packages/django/db/backends/utils.py", line 64, in execute
    return self.cursor.execute(sql, params)
  File "/root/zuoyuan/python3/lib/python3.5/site-packages/django/db/backends/mysql/base.py", line 124, in execute
    return self.cursor.execute(query, args)
  File "/root/zuoyuan/python3/lib/python3.5/site-packages/pymysql/cursors.py", line 166, in execute
    result = self._query(query)
  File "/root/zuoyuan/python3/lib/python3.5/site-packages/pymysql/cursors.py", line 322, in _query
    conn.query(q)
  File "/root/zuoyuan/python3/lib/python3.5/site-packages/pymysql/connections.py", line 856, in query
    self._affected_rows = self._read_query_result(unbuffered=unbuffered)
  File "/root/zuoyuan/python3/lib/python3.5/site-packages/pymysql/connections.py", line 1057, in _read_query_result
    result.read()
  File "/root/zuoyuan/python3/lib/python3.5/site-packages/pymysql/connections.py", line 1340, in read
    first_packet = self.connection._read_packet()
  File "/root/zuoyuan/python3/lib/python3.5/site-packages/pymysql/connections.py", line 1014, in _read_packet
    packet.check_error()
  File "/root/zuoyuan/python3/lib/python3.5/site-packages/pymysql/connections.py", line 393, in check_error
    err.raise_mysql_exception(self._data)
  File "/root/zuoyuan/python3/lib/python3.5/site-packages/pymysql/err.py", line 107, in raise_mysql_exception
    raise errorclass(errno, errval)
pymysql.err.DataError: (1406, "Data too long for column 'zip_code' at row 1")

The above exception was the direct cause of the following exception:

Traceback (most recent call last):
  File "/root/zuoyuan/python3/lib/python3.5/site-packages/django/core/handlers/base.py", line 132, in get_response
    response = wrapped_callback(request, *callback_args, **callback_kwargs)
  File "/root/yun/mybookstore/utils/utils.py", line 11, in wrapper
    return view_func(request, *view_args, **view_kwargs)
  File "/root/yun/mybookstore/users/views.py", line 236, in address
    zip_code=zip_code
  File "/root/yun/mybookstore/users/models.py", line 91, in add_one_address
    is_default=is_default)
  File "/root/zuoyuan/python3/lib/python3.5/site-packages/django/db/models/manager.py", line 127, in manager_method
    return getattr(self.get_queryset(), name)(*args, **kwargs)
  File "/root/zuoyuan/python3/lib/python3.5/site-packages/django/db/models/query.py", line 348, in create
    obj.save(force_insert=True, using=self.db)
  File "/root/zuoyuan/python3/lib/python3.5/site-packages/django/db/models/base.py", line 710, in save
    force_update=force_update, update_fields=update_fields)
  File "/root/zuoyuan/python3/lib/python3.5/site-packages/django/db/models/base.py", line 738, in save_base
    updated = self._save_table(raw, cls, force_insert, force_update, using, update_fields)
  File "/root/zuoyuan/python3/lib/python3.5/site-packages/django/db/models/base.py", line 822, in _save_table
    result = self._do_insert(cls._base_manager, using, fields, update_pk, raw)
  File "/root/zuoyuan/python3/lib/python3.5/site-packages/django/db/models/base.py", line 861, in _do_insert
    using=using, raw=raw)
  File "/root/zuoyuan/python3/lib/python3.5/site-packages/django/db/models/manager.py", line 127, in manager_method
    return getattr(self.get_queryset(), name)(*args, **kwargs)
  File "/root/zuoyuan/python3/lib/python3.5/site-packages/django/db/models/query.py", line 920, in _insert
    return query.get_compiler(using=using).execute_sql(return_id)
  File "/root/zuoyuan/python3/lib/python3.5/site-packages/django/db/models/sql/compiler.py", line 974, in execute_sql
    cursor.execute(sql, params)
  File "/root/zuoyuan/python3/lib/python3.5/site-packages/django/db/backends/utils.py", line 79, in execute
    return super(CursorDebugWrapper, self).execute(sql, params)
  File "/root/zuoyuan/python3/lib/python3.5/site-packages/django/db/backends/utils.py", line 64, in execute
    return self.cursor.execute(sql, params)
  File "/root/zuoyuan/python3/lib/python3.5/site-packages/django/db/utils.py", line 97, in __exit__
    six.reraise(dj_exc_type, dj_exc_value, traceback)
  File "/root/zuoyuan/python3/lib/python3.5/site-packages/django/utils/six.py", line 658, in reraise
    raise value.with_traceback(tb)
  File "/root/zuoyuan/python3/lib/python3.5/site-packages/django/db/backends/utils.py", line 64, in execute
    return self.cursor.execute(sql, params)
  File "/root/zuoyuan/python3/lib/python3.5/site-packages/django/db/backends/mysql/base.py", line 124, in execute
    return self.cursor.execute(query, args)
  File "/root/zuoyuan/python3/lib/python3.5/site-packages/pymysql/cursors.py", line 166, in execute
    result = self._query(query)
  File "/root/zuoyuan/python3/lib/python3.5/site-packages/pymysql/cursors.py", line 322, in _query
    conn.query(q)
  File "/root/zuoyuan/python3/lib/python3.5/site-packages/pymysql/connections.py", line 856, in query
    self._affected_rows = self._read_query_result(unbuffered=unbuffered)
  File "/root/zuoyuan/python3/lib/python3.5/site-packages/pymysql/connections.py", line 1057, in _read_query_result
    result.read()
  File "/root/zuoyuan/python3/lib/python3.5/site-packages/pymysql/connections.py", line 1340, in read
    first_packet = self.connection._read_packet()
  File "/root/zuoyuan/python3/lib/python3.5/site-packages/pymysql/connections.py", line 1014, in _read_packet
    packet.check_error()
  File "/root/zuoyuan/python3/lib/python3.5/site-packages/pymysql/connections.py", line 393, in check_error
    err.raise_mysql_exception(self._data)
  File "/root/zuoyuan/python3/lib/python3.5/site-packages/pymysql/err.py", line 107, in raise_mysql_exception
    raise errorclass(errno, errval)
django.db.utils.DataError: (1406, "Data too long for column 'zip_code' at row 1")
ERROR Internal Server Error: /user/address/
Traceback (most recent call last):
  File "/root/zuoyuan/python3/lib/python3.5/site-packages/django/db/backends/utils.py", line 64, in execute
    return self.cursor.execute(sql, params)
  File "/root/zuoyuan/python3/lib/python3.5/site-packages/django/db/backends/mysql/base.py", line 124, in execute
    return self.cursor.execute(query, args)
  File "/root/zuoyuan/python3/lib/python3.5/site-packages/pymysql/cursors.py", line 166, in execute
    result = self._query(query)
  File "/root/zuoyuan/python3/lib/python3.5/site-packages/pymysql/cursors.py", line 322, in _query
    conn.query(q)
  File "/root/zuoyuan/python3/lib/python3.5/site-packages/pymysql/connections.py", line 856, in query
    self._affected_rows = self._read_query_result(unbuffered=unbuffered)
  File "/root/zuoyuan/python3/lib/python3.5/site-packages/pymysql/connections.py", line 1057, in _read_query_result
    result.read()
  File "/root/zuoyuan/python3/lib/python3.5/site-packages/pymysql/connections.py", line 1340, in read
    first_packet = self.connection._read_packet()
  File "/root/zuoyuan/python3/lib/python3.5/site-packages/pymysql/connections.py", line 1014, in _read_packet
    packet.check_error()
  File "/root/zuoyuan/python3/lib/python3.5/site-packages/pymysql/connections.py", line 393, in check_error
    err.raise_mysql_exception(self._data)
  File "/root/zuoyuan/python3/lib/python3.5/site-packages/pymysql/err.py", line 107, in raise_mysql_exception
    raise errorclass(errno, errval)
pymysql.err.DataError: (1406, "Data too long for column 'zip_code' at row 1")

The above exception was the direct cause of the following exception:

Traceback (most recent call last):
  File "/root/zuoyuan/python3/lib/python3.5/site-packages/django/core/handlers/base.py", line 132, in get_response
    response = wrapped_callback(request, *callback_args, **callback_kwargs)
  File "/root/yun/mybookstore/utils/utils.py", line 11, in wrapper
    return view_func(request, *view_args, **view_kwargs)
  File "/root/yun/mybookstore/users/views.py", line 236, in address
    zip_code=zip_code
  File "/root/yun/mybookstore/users/models.py", line 91, in add_one_address
    is_default=is_default)
  File "/root/zuoyuan/python3/lib/python3.5/site-packages/django/db/models/manager.py", line 127, in manager_method
    return getattr(self.get_queryset(), name)(*args, **kwargs)
  File "/root/zuoyuan/python3/lib/python3.5/site-packages/django/db/models/query.py", line 348, in create
    obj.save(force_insert=True, using=self.db)
  File "/root/zuoyuan/python3/lib/python3.5/site-packages/django/db/models/base.py", line 710, in save
    force_update=force_update, update_fields=update_fields)
  File "/root/zuoyuan/python3/lib/python3.5/site-packages/django/db/models/base.py", line 738, in save_base
    updated = self._save_table(raw, cls, force_insert, force_update, using, update_fields)
  File "/root/zuoyuan/python3/lib/python3.5/site-packages/django/db/models/base.py", line 822, in _save_table
    result = self._do_insert(cls._base_manager, using, fields, update_pk, raw)
  File "/root/zuoyuan/python3/lib/python3.5/site-packages/django/db/models/base.py", line 861, in _do_insert
    using=using, raw=raw)
  File "/root/zuoyuan/python3/lib/python3.5/site-packages/django/db/models/manager.py", line 127, in manager_method
    return getattr(self.get_queryset(), name)(*args, **kwargs)
  File "/root/zuoyuan/python3/lib/python3.5/site-packages/django/db/models/query.py", line 920, in _insert
    return query.get_compiler(using=using).execute_sql(return_id)
  File "/root/zuoyuan/python3/lib/python3.5/site-packages/django/db/models/sql/compiler.py", line 974, in execute_sql
    cursor.execute(sql, params)
  File "/root/zuoyuan/python3/lib/python3.5/site-packages/django/db/backends/utils.py", line 79, in execute
    return super(CursorDebugWrapper, self).execute(sql, params)
  File "/root/zuoyuan/python3/lib/python3.5/site-packages/django/db/backends/utils.py", line 64, in execute
    return self.cursor.execute(sql, params)
  File "/root/zuoyuan/python3/lib/python3.5/site-packages/django/db/utils.py", line 97, in __exit__
    six.reraise(dj_exc_type, dj_exc_value, traceback)
  File "/root/zuoyuan/python3/lib/python3.5/site-packages/django/utils/six.py", line 658, in reraise
    raise value.with_traceback(tb)
  File "/root/zuoyuan/python3/lib/python3.5/site-packages/django/db/backends/utils.py", line 64, in execute
    return self.cursor.execute(sql, params)
  File "/root/zuoyuan/python3/lib/python3.5/site-packages/django/db/backends/mysql/base.py", line 124, in execute
    return self.cursor.execute(query, args)
  File "/root/zuoyuan/python3/lib/python3.5/site-packages/pymysql/cursors.py", line 166, in execute
    result = self._query(query)
  File "/root/zuoyuan/python3/lib/python3.5/site-packages/pymysql/cursors.py", line 322, in _query
    conn.query(q)
  File "/root/zuoyuan/python3/lib/python3.5/site-packages/pymysql/connections.py", line 856, in query
    self._affected_rows = self._read_query_result(unbuffered=unbuffered)
  File "/root/zuoyuan/python3/lib/python3.5/site-packages/pymysql/connections.py", line 1057, in _read_query_result
    result.read()
  File "/root/zuoyuan/python3/lib/python3.5/site-packages/pymysql/connections.py", line 1340, in read
    first_packet = self.connection._read_packet()
  File "/root/zuoyuan/python3/lib/python3.5/site-packages/pymysql/connections.py", line 1014, in _read_packet
    packet.check_error()
  File "/root/zuoyuan/python3/lib/python3.5/site-packages/pymysql/connections.py", line 393, in check_error
    err.raise_mysql_exception(self._data)
  File "/root/zuoyuan/python3/lib/python3.5/site-packages/pymysql/err.py", line 107, in raise_mysql_exception
    raise errorclass(errno, errval)
django.db.utils.DataError: (1406, "Data too long for column 'zip_code' at row 1")
INFO <django.contrib.sessions.backends.cache.SessionStore object at 0x7f568b3cf400>
INFO <django.contrib.sessions.backends.cache.SessionStore object at 0x7f568b3cf400>
WARNING Not Found: /comment/comment/undefined
WARNING Not Found: /comment/comment/undefined
INFO <django.contrib.sessions.backends.cache.SessionStore object at 0x7f568bad8da0>
INFO <django.contrib.sessions.backends.cache.SessionStore object at 0x7f568bad8da0>
WARNING Not Found: /comment/comment/undefined
WARNING Not Found: /comment/comment/undefined
WARNING Not Found: /comment/comment/undefined
WARNING Not Found: /comment/comment/undefined
WARNING Not Found: /comment/comment/undefined
WARNING Not Found: /comment/comment/undefined
INFO <django.contrib.sessions.backends.cache.SessionStore object at 0x7f568bb2a4e0>
INFO <django.contrib.sessions.backends.cache.SessionStore object at 0x7f568bb2a4e0>
WARNING Not Found: /comment/comment/undefined
WARNING Not Found: /comment/comment/undefined
INFO <django.contrib.sessions.backends.cache.SessionStore object at 0x7f568fccceb8>
INFO <django.contrib.sessions.backends.cache.SessionStore object at 0x7f568fccceb8>
INFO <django.contrib.sessions.backends.cache.SessionStore object at 0x7f568fe43630>
INFO <django.contrib.sessions.backends.cache.SessionStore object at 0x7f568fe43630>
INFO <django.contrib.sessions.backends.cache.SessionStore object at 0x7f568fcea828>
INFO <django.contrib.sessions.backends.cache.SessionStore object at 0x7f568fcea828>
INFO <django.contrib.sessions.backends.cache.SessionStore object at 0x7f569195c6a0>
INFO <django.contrib.sessions.backends.cache.SessionStore object at 0x7f569195c6a0>
INFO <django.contrib.sessions.backends.cache.SessionStore object at 0x7f568fd039e8>
INFO <django.contrib.sessions.backends.cache.SessionStore object at 0x7f568fd039e8>
INFO <django.contrib.sessions.backends.cache.SessionStore object at 0x7f568babe630>
INFO <django.contrib.sessions.backends.cache.SessionStore object at 0x7f568babe630>
INFO <django.contrib.sessions.backends.cache.SessionStore object at 0x7f568b3c21d0>
INFO <django.contrib.sessions.backends.cache.SessionStore object at 0x7f568b3c21d0>
INFO <django.contrib.sessions.backends.cache.SessionStore object at 0x7f568baf0eb8>
INFO <django.contrib.sessions.backends.cache.SessionStore object at 0x7f568baf0eb8>
INFO <django.contrib.sessions.backends.cache.SessionStore object at 0x7f568feb8160>
INFO <django.contrib.sessions.backends.cache.SessionStore object at 0x7f568feb8160>
INFO <django.contrib.sessions.backends.cache.SessionStore object at 0x7f568bae6cc0>
INFO <django.contrib.sessions.backends.cache.SessionStore object at 0x7f568bae6cc0>
INFO <django.contrib.sessions.backends.cache.SessionStore object at 0x7f568b3838d0>
INFO <django.contrib.sessions.backends.cache.SessionStore object at 0x7f568b3838d0>
INFO <django.contrib.sessions.backends.cache.SessionStore object at 0x7f568b3d0240>
INFO <django.contrib.sessions.backends.cache.SessionStore object at 0x7f568b3d0240>
INFO <django.contrib.sessions.backends.cache.SessionStore object at 0x7f568b4d1c88>
INFO <django.contrib.sessions.backends.cache.SessionStore object at 0x7f568b4d1c88>
WARNING Not Found: /favicon.ico
WARNING Not Found: /favicon.ico
INFO <django.contrib.sessions.backends.cache.SessionStore object at 0x7f568b3c4d30>
INFO <django.contrib.sessions.backends.cache.SessionStore object at 0x7f568b3c4d30>
INFO <django.contrib.sessions.backends.cache.SessionStore object at 0x7f568b4dbbe0>
INFO <django.contrib.sessions.backends.cache.SessionStore object at 0x7f568b4dbbe0>
INFO <django.contrib.sessions.backends.cache.SessionStore object at 0x7f568fb88da0>
INFO <django.contrib.sessions.backends.cache.SessionStore object at 0x7f568fb88da0>
